2018-04-16 09:39:49,229 level-ERROR    zhengtao is logging and permission is [u'resetdate', u'sqlcommand', u'checkversion', u'gmcommand', u'closeserver', u'openserver', u'servermanager', u'displayresetversion', u'checkserverstat', u'bootgame', u'update_front', u'update_javascripts', u'update_java', u'ywupdate', u'ywtools', u'javalog', u'phplog', u'logs', u'permission', u'role', u'user', u'system', u'root']
2018-04-16 09:39:49,404 level-ERROR    AllPlatMsg is [{'gameAlias': u'bxcq', 'platformId': 2, 'platformAlias': u'qq', 'gameId': 27, 'configId': 1, 'platformName': u'qq'}, {'gameAlias': u'bxcq', 'platformId': 14, 'platformAlias': u'tencent', 'gameId': 27, 'configId': 2, 'platformName': u'tencent'}, {'gameAlias': u'bxcq', 'platformId': 15, 'platformAlias': u'108qu_rxsj', 'gameId': 27, 'configId': 3, 'platformName': u'108qu_rxsj'}, {'gameAlias': u'bxcq', 'platformId': 16, 'platformAlias': u'bengwan_rxsj', 'gameId': 27, 'configId': 4, 'platformName': u'bengwan_rxsj'}, {'gameAlias': u'bxcq', 'platformId': 17, 'platformAlias': u'354yx_rxsj', 'gameId': 27, 'configId': 5, 'platformName': u'354yx_rxsj'}, {'gameAlias': u'bxcq', 'platformId': 18, 'platformAlias': u'6344_rxsj', 'gameId': 27, 'configId': 6, 'platformName': u'6344_rxsj'}, {'gameAlias': u'bxcq', 'platformId': 19, 'platformAlias': u'mayi_rxsj', 'gameId': 27, 'configId': 7, 'platformName': u'mayi_rxsj'}, {'gameAlias': u'bxcq', 'platformId': 20, 'platformAlias': u'yaowan_rxsj', 'gameId': 27, 'configId': 8, 'platformName': u'yaowan_rxsj'}]
2018-04-16 10:39:34,744 level-ERROR    zhengtao is logging and permission is [u'resetdate', u'sqlcommand', u'checkversion', u'gmcommand', u'closeserver', u'openserver', u'servermanager', u'displayresetversion', u'checkserverstat', u'bootgame', u'update_front', u'update_javascripts', u'update_java', u'ywupdate', u'ywtools', u'javalog', u'phplog', u'logs', u'permission', u'role', u'user', u'system', u'root']
2018-04-16 10:39:34,876 level-ERROR    AllPlatMsg is [{'gameAlias': u'bxcq', 'platformId': 2, 'platformAlias': u'qq', 'gameId': 27, 'configId': 1, 'platformName': u'qq'}, {'gameAlias': u'bxcq', 'platformId': 14, 'platformAlias': u'tencent', 'gameId': 27, 'configId': 2, 'platformName': u'tencent'}, {'gameAlias': u'bxcq', 'platformId': 15, 'platformAlias': u'108qu_rxsj', 'gameId': 27, 'configId': 3, 'platformName': u'108qu_rxsj'}, {'gameAlias': u'bxcq', 'platformId': 16, 'platformAlias': u'bengwan_rxsj', 'gameId': 27, 'configId': 4, 'platformName': u'bengwan_rxsj'}, {'gameAlias': u'bxcq', 'platformId': 17, 'platformAlias': u'354yx_rxsj', 'gameId': 27, 'configId': 5, 'platformName': u'354yx_rxsj'}, {'gameAlias': u'bxcq', 'platformId': 18, 'platformAlias': u'6344_rxsj', 'gameId': 27, 'configId': 6, 'platformName': u'6344_rxsj'}, {'gameAlias': u'bxcq', 'platformId': 19, 'platformAlias': u'mayi_rxsj', 'gameId': 27, 'configId': 7, 'platformName': u'mayi_rxsj'}, {'gameAlias': u'bxcq', 'platformId': 20, 'platformAlias': u'yaowan_rxsj', 'gameId': 27, 'configId': 8, 'platformName': u'yaowan_rxsj'}]
2018-04-16 10:57:43,022 level-ERROR    Traceback (most recent call last):
  File "/data/BxcqMloms/app/mylibs/sendsocket.py", line 10, in send_socket
    SendSocket.connect(addr)
  File "<string>", line 1, in connect
error: [Errno 111] Connection refused

2018-04-16 10:57:43,023 level-ERROR    Traceback (most recent call last):
  File "/data/BxcqMloms/app/api/views.py", line 121, in CollectLoad
    loads = ipsLoadJson[i]['load']
KeyError: 0

2018-04-16 10:59:55,401 level-ERROR    zhengtao is logging and permission is [u'resetdate', u'sqlcommand', u'checkversion', u'gmcommand', u'closeserver', u'openserver', u'servermanager', u'displayresetversion', u'checkserverstat', u'bootgame', u'update_front', u'update_javascripts', u'update_java', u'ywupdate', u'ywtools', u'javalog', u'phplog', u'logs', u'permission', u'role', u'user', u'system', u'root']
2018-04-16 10:59:55,582 level-ERROR    AllPlatMsg is [{'gameAlias': u'bxcq', 'platformId': 2, 'platformAlias': u'qq', 'gameId': 27, 'configId': 1, 'platformName': u'qq'}, {'gameAlias': u'bxcq', 'platformId': 14, 'platformAlias': u'tencent', 'gameId': 27, 'configId': 2, 'platformName': u'tencent'}, {'gameAlias': u'bxcq', 'platformId': 15, 'platformAlias': u'108qu_rxsj', 'gameId': 27, 'configId': 3, 'platformName': u'108qu_rxsj'}, {'gameAlias': u'bxcq', 'platformId': 16, 'platformAlias': u'bengwan_rxsj', 'gameId': 27, 'configId': 4, 'platformName': u'bengwan_rxsj'}, {'gameAlias': u'bxcq', 'platformId': 17, 'platformAlias': u'354yx_rxsj', 'gameId': 27, 'configId': 5, 'platformName': u'354yx_rxsj'}, {'gameAlias': u'bxcq', 'platformId': 18, 'platformAlias': u'6344_rxsj', 'gameId': 27, 'configId': 6, 'platformName': u'6344_rxsj'}, {'gameAlias': u'bxcq', 'platformId': 19, 'platformAlias': u'mayi_rxsj', 'gameId': 27, 'configId': 7, 'platformName': u'mayi_rxsj'}, {'gameAlias': u'bxcq', 'platformId': 20, 'platformAlias': u'yaowan_rxsj', 'gameId': 27, 'configId': 8, 'platformName': u'yaowan_rxsj'}]
2018-04-16 11:02:43,076 level-ERROR    Traceback (most recent call last):
  File "/data/BxcqMloms/app/mylibs/sendsocket.py", line 10, in send_socket
    SendSocket.connect(addr)
  File "<string>", line 1, in connect
error: [Errno 111] Connection refused

2018-04-16 11:02:43,077 level-ERROR    Traceback (most recent call last):
  File "/data/BxcqMloms/app/api/views.py", line 121, in CollectLoad
    loads = ipsLoadJson[i]['load']
KeyError: 0

2018-04-16 11:07:43,127 level-ERROR    Traceback (most recent call last):
  File "/data/BxcqMloms/app/mylibs/sendsocket.py", line 10, in send_socket
    SendSocket.connect(addr)
  File "<string>", line 1, in connect
error: [Errno 111] Connection refused

2018-04-16 11:07:43,127 level-ERROR    Traceback (most recent call last):
  File "/data/BxcqMloms/app/api/views.py", line 121, in CollectLoad
    loads = ipsLoadJson[i]['load']
KeyError: 0

2018-04-16 11:09:14,452 level-ERROR    Traceback (most recent call last):
  File "/data/BxcqMloms/app/mylibs/sendsocket.py", line 10, in send_socket
    SendSocket.connect(addr)
  File "<string>", line 1, in connect
error: [Errno 111] Connection refused

2018-04-16 11:09:14,452 level-ERROR    Exception on /checkState [POST]
Traceback (most recent call last):
  File "/usr/lib/python2.6/site-packages/flask/app.py", line 1982, in wsgi_app
    response = self.full_dispatch_request()
  File "/usr/lib/python2.6/site-packages/flask/app.py", line 1614, in full_dispatch_request
    rv = self.handle_user_exception(e)
  File "/usr/lib/python2.6/site-packages/flask/app.py", line 1517, in handle_user_exception
    reraise(exc_type, exc_value, tb)
  File "/usr/lib/python2.6/site-packages/flask/app.py", line 1612, in full_dispatch_request
    rv = self.dispatch_request()
  File "/usr/lib/python2.6/site-packages/flask/app.py", line 1598, in dispatch_request
    return self.view_functions[rule.endpoint](**req.view_args)
  File "/usr/lib/python2.6/site-packages/flask_login/utils.py", line 261, in decorated_view
    return func(*args, **kwargs)
  File "/data/BxcqMloms/app/decorators.py", line 8, in decorated_function
    return func(*args,**kwargs)
  File "/data/BxcqMloms/app/ywtools/views.py", line 498, in checkState
    if int(checkResultJson[xi]['code']) == 2:
KeyError: 0
2018-04-16 11:09:35,911 level-ERROR    Traceback (most recent call last):
  File "/data/BxcqMloms/app/mylibs/sendsocket.py", line 10, in send_socket
    SendSocket.connect(addr)
  File "<string>", line 1, in connect
error: [Errno 111] Connection refused

2018-04-16 11:09:35,912 level-ERROR    Exception on /checkState [POST]
Traceback (most recent call last):
  File "/usr/lib/python2.6/site-packages/flask/app.py", line 1982, in wsgi_app
    response = self.full_dispatch_request()
  File "/usr/lib/python2.6/site-packages/flask/app.py", line 1614, in full_dispatch_request
    rv = self.handle_user_exception(e)
  File "/usr/lib/python2.6/site-packages/flask/app.py", line 1517, in handle_user_exception
    reraise(exc_type, exc_value, tb)
  File "/usr/lib/python2.6/site-packages/flask/app.py", line 1612, in full_dispatch_request
    rv = self.dispatch_request()
  File "/usr/lib/python2.6/site-packages/flask/app.py", line 1598, in dispatch_request
    return self.view_functions[rule.endpoint](**req.view_args)
  File "/usr/lib/python2.6/site-packages/flask_login/utils.py", line 261, in decorated_view
    return func(*args, **kwargs)
  File "/data/BxcqMloms/app/decorators.py", line 8, in decorated_function
    return func(*args,**kwargs)
  File "/data/BxcqMloms/app/ywtools/views.py", line 498, in checkState
    if int(checkResultJson[xi]['code']) == 2:
KeyError: 0
2018-04-16 11:09:44,757 level-ERROR    Traceback (most recent call last):
  File "/data/BxcqMloms/app/mylibs/sendsocket.py", line 10, in send_socket
    SendSocket.connect(addr)
  File "<string>", line 1, in connect
error: [Errno 111] Connection refused

2018-04-16 11:09:44,757 level-ERROR    Exception on /checkState [POST]
Traceback (most recent call last):
  File "/usr/lib/python2.6/site-packages/flask/app.py", line 1982, in wsgi_app
    response = self.full_dispatch_request()
  File "/usr/lib/python2.6/site-packages/flask/app.py", line 1614, in full_dispatch_request
    rv = self.handle_user_exception(e)
  File "/usr/lib/python2.6/site-packages/flask/app.py", line 1517, in handle_user_exception
    reraise(exc_type, exc_value, tb)
  File "/usr/lib/python2.6/site-packages/flask/app.py", line 1612, in full_dispatch_request
    rv = self.dispatch_request()
  File "/usr/lib/python2.6/site-packages/flask/app.py", line 1598, in dispatch_request
    return self.view_functions[rule.endpoint](**req.view_args)
  File "/usr/lib/python2.6/site-packages/flask_login/utils.py", line 261, in decorated_view
    return func(*args, **kwargs)
  File "/data/BxcqMloms/app/decorators.py", line 8, in decorated_function
    return func(*args,**kwargs)
  File "/data/BxcqMloms/app/ywtools/views.py", line 498, in checkState
    if int(checkResultJson[xi]['code']) == 2:
KeyError: 0
2018-04-16 11:09:49,781 level-ERROR    Traceback (most recent call last):
  File "/data/BxcqMloms/app/mylibs/sendsocket.py", line 10, in send_socket
    SendSocket.connect(addr)
  File "<string>", line 1, in connect
error: [Errno 111] Connection refused

2018-04-16 11:09:49,785 level-ERROR    Exception on /checkState [POST]
Traceback (most recent call last):
  File "/usr/lib/python2.6/site-packages/flask/app.py", line 1982, in wsgi_app
    response = self.full_dispatch_request()
  File "/usr/lib/python2.6/site-packages/flask/app.py", line 1614, in full_dispatch_request
    rv = self.handle_user_exception(e)
  File "/usr/lib/python2.6/site-packages/flask/app.py", line 1517, in handle_user_exception
    reraise(exc_type, exc_value, tb)
  File "/usr/lib/python2.6/site-packages/flask/app.py", line 1612, in full_dispatch_request
    rv = self.dispatch_request()
  File "/usr/lib/python2.6/site-packages/flask/app.py", line 1598, in dispatch_request
    return self.view_functions[rule.endpoint](**req.view_args)
  File "/usr/lib/python2.6/site-packages/flask_login/utils.py", line 261, in decorated_view
    return func(*args, **kwargs)
  File "/data/BxcqMloms/app/decorators.py", line 8, in decorated_function
    return func(*args,**kwargs)
  File "/data/BxcqMloms/app/ywtools/views.py", line 489, in checkState
    if int(checkResultJson[xi]['code']) == 0:
KeyError: 0
2018-04-16 11:11:10,408 level-ERROR    Traceback (most recent call last):
  File "/data/BxcqMloms/app/mylibs/sendsocket.py", line 10, in send_socket
    SendSocket.connect(addr)
  File "<string>", line 1, in connect
error: [Errno 111] Connection refused

2018-04-16 11:11:10,409 level-ERROR    Exception on /checkState [POST]
Traceback (most recent call last):
  File "/usr/lib/python2.6/site-packages/flask/app.py", line 1982, in wsgi_app
    response = self.full_dispatch_request()
  File "/usr/lib/python2.6/site-packages/flask/app.py", line 1614, in full_dispatch_request
    rv = self.handle_user_exception(e)
  File "/usr/lib/python2.6/site-packages/flask/app.py", line 1517, in handle_user_exception
    reraise(exc_type, exc_value, tb)
  File "/usr/lib/python2.6/site-packages/flask/app.py", line 1612, in full_dispatch_request
    rv = self.dispatch_request()
  File "/usr/lib/python2.6/site-packages/flask/app.py", line 1598, in dispatch_request
    return self.view_functions[rule.endpoint](**req.view_args)
  File "/usr/lib/python2.6/site-packages/flask_login/utils.py", line 261, in decorated_view
    return func(*args, **kwargs)
  File "/data/BxcqMloms/app/decorators.py", line 8, in decorated_function
    return func(*args,**kwargs)
  File "/data/BxcqMloms/app/ywtools/views.py", line 489, in checkState
    if int(checkResultJson[xi]['code']) == 0:
KeyError: 0
2018-04-16 11:11:12,140 level-ERROR    Traceback (most recent call last):
  File "/data/BxcqMloms/app/mylibs/sendsocket.py", line 10, in send_socket
    SendSocket.connect(addr)
  File "<string>", line 1, in connect
error: [Errno 111] Connection refused

2018-04-16 11:11:12,140 level-ERROR    Exception on /checkState [POST]
Traceback (most recent call last):
  File "/usr/lib/python2.6/site-packages/flask/app.py", line 1982, in wsgi_app
    response = self.full_dispatch_request()
  File "/usr/lib/python2.6/site-packages/flask/app.py", line 1614, in full_dispatch_request
    rv = self.handle_user_exception(e)
  File "/usr/lib/python2.6/site-packages/flask/app.py", line 1517, in handle_user_exception
    reraise(exc_type, exc_value, tb)
  File "/usr/lib/python2.6/site-packages/flask/app.py", line 1612, in full_dispatch_request
    rv = self.dispatch_request()
  File "/usr/lib/python2.6/site-packages/flask/app.py", line 1598, in dispatch_request
    return self.view_functions[rule.endpoint](**req.view_args)
  File "/usr/lib/python2.6/site-packages/flask_login/utils.py", line 261, in decorated_view
    return func(*args, **kwargs)
  File "/data/BxcqMloms/app/decorators.py", line 8, in decorated_function
    return func(*args,**kwargs)
  File "/data/BxcqMloms/app/ywtools/views.py", line 489, in checkState
    if int(checkResultJson[xi]['code']) == 0:
KeyError: 0
2018-04-16 11:11:13,532 level-ERROR    Traceback (most recent call last):
  File "/data/BxcqMloms/app/mylibs/sendsocket.py", line 10, in send_socket
    SendSocket.connect(addr)
  File "<string>", line 1, in connect
error: [Errno 111] Connection refused

2018-04-16 11:11:13,534 level-ERROR    Exception on /checkState [POST]
Traceback (most recent call last):
  File "/usr/lib/python2.6/site-packages/flask/app.py", line 1982, in wsgi_app
    response = self.full_dispatch_request()
  File "/usr/lib/python2.6/site-packages/flask/app.py", line 1614, in full_dispatch_request
    rv = self.handle_user_exception(e)
  File "/usr/lib/python2.6/site-packages/flask/app.py", line 1517, in handle_user_exception
    reraise(exc_type, exc_value, tb)
  File "/usr/lib/python2.6/site-packages/flask/app.py", line 1612, in full_dispatch_request
    rv = self.dispatch_request()
  File "/usr/lib/python2.6/site-packages/flask/app.py", line 1598, in dispatch_request
    return self.view_functions[rule.endpoint](**req.view_args)
  File "/usr/lib/python2.6/site-packages/flask_login/utils.py", line 261, in decorated_view
    return func(*args, **kwargs)
  File "/data/BxcqMloms/app/decorators.py", line 8, in decorated_function
    return func(*args,**kwargs)
  File "/data/BxcqMloms/app/ywtools/views.py", line 489, in checkState
    if int(checkResultJson[xi]['code']) == 0:
KeyError: 0
2018-04-16 11:11:28,202 level-ERROR    yangyang is logging and permission is [u'root', u'update_front', u'ywupdate', u'ywtools']
2018-04-16 11:11:28,347 level-ERROR    AllPlatMsg is [{'gameAlias': u'bxcq', 'platformId': 2, 'platformAlias': u'qq', 'gameId': 27, 'configId': 1, 'platformName': u'qq'}, {'gameAlias': u'bxcq', 'platformId': 14, 'platformAlias': u'tencent', 'gameId': 27, 'configId': 2, 'platformName': u'tencent'}, {'gameAlias': u'bxcq', 'platformId': 15, 'platformAlias': u'108qu_rxsj', 'gameId': 27, 'configId': 3, 'platformName': u'108qu_rxsj'}, {'gameAlias': u'bxcq', 'platformId': 16, 'platformAlias': u'bengwan_rxsj', 'gameId': 27, 'configId': 4, 'platformName': u'bengwan_rxsj'}, {'gameAlias': u'bxcq', 'platformId': 17, 'platformAlias': u'354yx_rxsj', 'gameId': 27, 'configId': 5, 'platformName': u'354yx_rxsj'}, {'gameAlias': u'bxcq', 'platformId': 18, 'platformAlias': u'6344_rxsj', 'gameId': 27, 'configId': 6, 'platformName': u'6344_rxsj'}, {'gameAlias': u'bxcq', 'platformId': 19, 'platformAlias': u'mayi_rxsj', 'gameId': 27, 'configId': 7, 'platformName': u'mayi_rxsj'}, {'gameAlias': u'bxcq', 'platformId': 20, 'platformAlias': u'yaowan_rxsj', 'gameId': 27, 'configId': 8, 'platformName': u'yaowan_rxsj'}]
2018-04-16 11:11:30,790 level-ERROR    Traceback (most recent call last):
  File "/data/BxcqMloms/app/mylibs/sendsocket.py", line 10, in send_socket
    SendSocket.connect(addr)
  File "<string>", line 1, in connect
error: [Errno 111] Connection refused

2018-04-16 11:11:30,791 level-ERROR    Exception on /checkState [POST]
Traceback (most recent call last):
  File "/usr/lib/python2.6/site-packages/flask/app.py", line 1982, in wsgi_app
    response = self.full_dispatch_request()
  File "/usr/lib/python2.6/site-packages/flask/app.py", line 1614, in full_dispatch_request
    rv = self.handle_user_exception(e)
  File "/usr/lib/python2.6/site-packages/flask/app.py", line 1517, in handle_user_exception
    reraise(exc_type, exc_value, tb)
  File "/usr/lib/python2.6/site-packages/flask/app.py", line 1612, in full_dispatch_request
    rv = self.dispatch_request()
  File "/usr/lib/python2.6/site-packages/flask/app.py", line 1598, in dispatch_request
    return self.view_functions[rule.endpoint](**req.view_args)
  File "/usr/lib/python2.6/site-packages/flask_login/utils.py", line 261, in decorated_view
    return func(*args, **kwargs)
  File "/data/BxcqMloms/app/decorators.py", line 8, in decorated_function
    return func(*args,**kwargs)
  File "/data/BxcqMloms/app/ywtools/views.py", line 489, in checkState
    if int(checkResultJson[xi]['code']) == 0:
KeyError: 0
2018-04-16 11:11:32,798 level-ERROR    Traceback (most recent call last):
  File "/data/BxcqMloms/app/mylibs/sendsocket.py", line 10, in send_socket
    SendSocket.connect(addr)
  File "<string>", line 1, in connect
error: [Errno 111] Connection refused

2018-04-16 11:11:32,798 level-ERROR    Exception on /checkState [POST]
Traceback (most recent call last):
  File "/usr/lib/python2.6/site-packages/flask/app.py", line 1982, in wsgi_app
    response = self.full_dispatch_request()
  File "/usr/lib/python2.6/site-packages/flask/app.py", line 1614, in full_dispatch_request
    rv = self.handle_user_exception(e)
  File "/usr/lib/python2.6/site-packages/flask/app.py", line 1517, in handle_user_exception
    reraise(exc_type, exc_value, tb)
  File "/usr/lib/python2.6/site-packages/flask/app.py", line 1612, in full_dispatch_request
    rv = self.dispatch_request()
  File "/usr/lib/python2.6/site-packages/flask/app.py", line 1598, in dispatch_request
    return self.view_functions[rule.endpoint](**req.view_args)
  File "/usr/lib/python2.6/site-packages/flask_login/utils.py", line 261, in decorated_view
    return func(*args, **kwargs)
  File "/data/BxcqMloms/app/decorators.py", line 8, in decorated_function
    return func(*args,**kwargs)
  File "/data/BxcqMloms/app/ywtools/views.py", line 489, in checkState
    if int(checkResultJson[xi]['code']) == 0:
KeyError: 0
2018-04-16 11:11:50,241 level-ERROR    Traceback (most recent call last):
  File "/data/BxcqMloms/app/mylibs/sendsocket.py", line 10, in send_socket
    SendSocket.connect(addr)
  File "<string>", line 1, in connect
error: [Errno 111] Connection refused

2018-04-16 11:11:50,244 level-ERROR    Exception on /checkState [POST]
Traceback (most recent call last):
  File "/usr/lib/python2.6/site-packages/flask/app.py", line 1982, in wsgi_app
    response = self.full_dispatch_request()
  File "/usr/lib/python2.6/site-packages/flask/app.py", line 1614, in full_dispatch_request
    rv = self.handle_user_exception(e)
  File "/usr/lib/python2.6/site-packages/flask/app.py", line 1517, in handle_user_exception
    reraise(exc_type, exc_value, tb)
  File "/usr/lib/python2.6/site-packages/flask/app.py", line 1612, in full_dispatch_request
    rv = self.dispatch_request()
  File "/usr/lib/python2.6/site-packages/flask/app.py", line 1598, in dispatch_request
    return self.view_functions[rule.endpoint](**req.view_args)
  File "/usr/lib/python2.6/site-packages/flask_login/utils.py", line 261, in decorated_view
    return func(*args, **kwargs)
  File "/data/BxcqMloms/app/decorators.py", line 8, in decorated_function
    return func(*args,**kwargs)
  File "/data/BxcqMloms/app/ywtools/views.py", line 489, in checkState
    if int(checkResultJson[xi]['code']) == 0:
KeyError: 0
2018-04-16 11:12:43,228 level-ERROR    Traceback (most recent call last):
  File "/data/BxcqMloms/app/mylibs/sendsocket.py", line 10, in send_socket
    SendSocket.connect(addr)
  File "<string>", line 1, in connect
error: [Errno 111] Connection refused

2018-04-16 11:12:43,229 level-ERROR    Traceback (most recent call last):
  File "/data/BxcqMloms/app/api/views.py", line 121, in CollectLoad
    loads = ipsLoadJson[i]['load']
KeyError: 0

2018-04-16 11:13:00,788 level-ERROR    [Errno 111] Connection refused
2018-04-16 11:15:06,363 level-ERROR    Traceback (most recent call last):
  File "/data/BxcqMloms/app/mylibs/sendsocket.py", line 10, in send_socket
    SendSocket.connect(addr)
  File "<string>", line 1, in connect
error: [Errno 111] Connection refused

2018-04-16 11:15:06,364 level-ERROR    Exception on /checkState [POST]
Traceback (most recent call last):
  File "/usr/lib/python2.6/site-packages/flask/app.py", line 1982, in wsgi_app
    response = self.full_dispatch_request()
  File "/usr/lib/python2.6/site-packages/flask/app.py", line 1614, in full_dispatch_request
    rv = self.handle_user_exception(e)
  File "/usr/lib/python2.6/site-packages/flask/app.py", line 1517, in handle_user_exception
    reraise(exc_type, exc_value, tb)
  File "/usr/lib/python2.6/site-packages/flask/app.py", line 1612, in full_dispatch_request
    rv = self.dispatch_request()
  File "/usr/lib/python2.6/site-packages/flask/app.py", line 1598, in dispatch_request
    return self.view_functions[rule.endpoint](**req.view_args)
  File "/usr/lib/python2.6/site-packages/flask_login/utils.py", line 261, in decorated_view
    return func(*args, **kwargs)
  File "/data/BxcqMloms/app/decorators.py", line 8, in decorated_function
    return func(*args,**kwargs)
  File "/data/BxcqMloms/app/ywtools/views.py", line 489, in checkState
    if int(checkResultJson[xi]['code']) == 0:
KeyError: 0
2018-04-16 11:15:08,198 level-ERROR    Traceback (most recent call last):
  File "/data/BxcqMloms/app/mylibs/sendsocket.py", line 10, in send_socket
    SendSocket.connect(addr)
  File "<string>", line 1, in connect
error: [Errno 111] Connection refused

2018-04-16 11:15:08,198 level-ERROR    Exception on /checkState [POST]
Traceback (most recent call last):
  File "/usr/lib/python2.6/site-packages/flask/app.py", line 1982, in wsgi_app
    response = self.full_dispatch_request()
  File "/usr/lib/python2.6/site-packages/flask/app.py", line 1614, in full_dispatch_request
    rv = self.handle_user_exception(e)
  File "/usr/lib/python2.6/site-packages/flask/app.py", line 1517, in handle_user_exception
    reraise(exc_type, exc_value, tb)
  File "/usr/lib/python2.6/site-packages/flask/app.py", line 1612, in full_dispatch_request
    rv = self.dispatch_request()
  File "/usr/lib/python2.6/site-packages/flask/app.py", line 1598, in dispatch_request
    return self.view_functions[rule.endpoint](**req.view_args)
  File "/usr/lib/python2.6/site-packages/flask_login/utils.py", line 261, in decorated_view
    return func(*args, **kwargs)
  File "/data/BxcqMloms/app/decorators.py", line 8, in decorated_function
    return func(*args,**kwargs)
  File "/data/BxcqMloms/app/ywtools/views.py", line 489, in checkState
    if int(checkResultJson[xi]['code']) == 0:
KeyError: 0
2018-04-16 11:16:09,799 level-ERROR    Traceback (most recent call last):
  File "/data/BxcqMloms/app/mylibs/sendsocket.py", line 10, in send_socket
    SendSocket.connect(addr)
  File "<string>", line 1, in connect
error: [Errno 111] Connection refused

2018-04-16 11:16:09,799 level-ERROR    Exception on /checkState [POST]
Traceback (most recent call last):
  File "/usr/lib/python2.6/site-packages/flask/app.py", line 1982, in wsgi_app
    response = self.full_dispatch_request()
  File "/usr/lib/python2.6/site-packages/flask/app.py", line 1614, in full_dispatch_request
    rv = self.handle_user_exception(e)
  File "/usr/lib/python2.6/site-packages/flask/app.py", line 1517, in handle_user_exception
    reraise(exc_type, exc_value, tb)
  File "/usr/lib/python2.6/site-packages/flask/app.py", line 1612, in full_dispatch_request
    rv = self.dispatch_request()
  File "/usr/lib/python2.6/site-packages/flask/app.py", line 1598, in dispatch_request
    return self.view_functions[rule.endpoint](**req.view_args)
  File "/usr/lib/python2.6/site-packages/flask_login/utils.py", line 261, in decorated_view
    return func(*args, **kwargs)
  File "/data/BxcqMloms/app/decorators.py", line 8, in decorated_function
    return func(*args,**kwargs)
  File "/data/BxcqMloms/app/ywtools/views.py", line 489, in checkState
    if int(checkResultJson[xi]['code']) == 0:
KeyError: 0
2018-04-16 11:16:11,374 level-ERROR    Traceback (most recent call last):
  File "/data/BxcqMloms/app/mylibs/sendsocket.py", line 10, in send_socket
    SendSocket.connect(addr)
  File "<string>", line 1, in connect
error: [Errno 111] Connection refused

2018-04-16 11:16:11,374 level-ERROR    Exception on /checkState [POST]
Traceback (most recent call last):
  File "/usr/lib/python2.6/site-packages/flask/app.py", line 1982, in wsgi_app
    response = self.full_dispatch_request()
  File "/usr/lib/python2.6/site-packages/flask/app.py", line 1614, in full_dispatch_request
    rv = self.handle_user_exception(e)
  File "/usr/lib/python2.6/site-packages/flask/app.py", line 1517, in handle_user_exception
    reraise(exc_type, exc_value, tb)
  File "/usr/lib/python2.6/site-packages/flask/app.py", line 1612, in full_dispatch_request
    rv = self.dispatch_request()
  File "/usr/lib/python2.6/site-packages/flask/app.py", line 1598, in dispatch_request
    return self.view_functions[rule.endpoint](**req.view_args)
  File "/usr/lib/python2.6/site-packages/flask_login/utils.py", line 261, in decorated_view
    return func(*args, **kwargs)
  File "/data/BxcqMloms/app/decorators.py", line 8, in decorated_function
    return func(*args,**kwargs)
  File "/data/BxcqMloms/app/ywtools/views.py", line 489, in checkState
    if int(checkResultJson[xi]['code']) == 0:
KeyError: 0
2018-04-16 11:16:18,276 level-ERROR    Traceback (most recent call last):
  File "/data/BxcqMloms/app/mylibs/sendsocket.py", line 10, in send_socket
    SendSocket.connect(addr)
  File "<string>", line 1, in connect
error: [Errno 111] Connection refused

2018-04-16 11:16:18,276 level-ERROR    Exception on /checkState [POST]
Traceback (most recent call last):
  File "/usr/lib/python2.6/site-packages/flask/app.py", line 1982, in wsgi_app
    response = self.full_dispatch_request()
  File "/usr/lib/python2.6/site-packages/flask/app.py", line 1614, in full_dispatch_request
    rv = self.handle_user_exception(e)
  File "/usr/lib/python2.6/site-packages/flask/app.py", line 1517, in handle_user_exception
    reraise(exc_type, exc_value, tb)
  File "/usr/lib/python2.6/site-packages/flask/app.py", line 1612, in full_dispatch_request
    rv = self.dispatch_request()
  File "/usr/lib/python2.6/site-packages/flask/app.py", line 1598, in dispatch_request
    return self.view_functions[rule.endpoint](**req.view_args)
  File "/usr/lib/python2.6/site-packages/flask_login/utils.py", line 261, in decorated_view
    return func(*args, **kwargs)
  File "/data/BxcqMloms/app/decorators.py", line 8, in decorated_function
    return func(*args,**kwargs)
  File "/data/BxcqMloms/app/ywtools/views.py", line 489, in checkState
    if int(checkResultJson[xi]['code']) == 0:
KeyError: 0
2018-04-16 11:17:26,332 level-ERROR    zhengtao is logging and permission is [u'resetdate', u'sqlcommand', u'checkversion', u'gmcommand', u'closeserver', u'openserver', u'servermanager', u'displayresetversion', u'checkserverstat', u'bootgame', u'update_front', u'update_javascripts', u'update_java', u'ywupdate', u'ywtools', u'javalog', u'phplog', u'logs', u'permission', u'role', u'user', u'system', u'root']
2018-04-16 11:17:26,471 level-ERROR    AllPlatMsg is [{'gameAlias': u'bxcq', 'platformId': 2, 'platformAlias': u'qq', 'gameId': 27, 'configId': 1, 'platformName': u'qq'}, {'gameAlias': u'bxcq', 'platformId': 14, 'platformAlias': u'tencent', 'gameId': 27, 'configId': 2, 'platformName': u'tencent'}, {'gameAlias': u'bxcq', 'platformId': 15, 'platformAlias': u'108qu_rxsj', 'gameId': 27, 'configId': 3, 'platformName': u'108qu_rxsj'}, {'gameAlias': u'bxcq', 'platformId': 16, 'platformAlias': u'bengwan_rxsj', 'gameId': 27, 'configId': 4, 'platformName': u'bengwan_rxsj'}, {'gameAlias': u'bxcq', 'platformId': 17, 'platformAlias': u'354yx_rxsj', 'gameId': 27, 'configId': 5, 'platformName': u'354yx_rxsj'}, {'gameAlias': u'bxcq', 'platformId': 18, 'platformAlias': u'6344_rxsj', 'gameId': 27, 'configId': 6, 'platformName': u'6344_rxsj'}, {'gameAlias': u'bxcq', 'platformId': 19, 'platformAlias': u'mayi_rxsj', 'gameId': 27, 'configId': 7, 'platformName': u'mayi_rxsj'}, {'gameAlias': u'bxcq', 'platformId': 20, 'platformAlias': u'yaowan_rxsj', 'gameId': 27, 'configId': 8, 'platformName': u'yaowan_rxsj'}]
2018-04-16 11:17:36,032 level-ERROR    Traceback (most recent call last):
  File "/data/BxcqMloms/app/mylibs/sendsocket.py", line 10, in send_socket
    SendSocket.connect(addr)
  File "<string>", line 1, in connect
error: [Errno 111] Connection refused

2018-04-16 11:17:36,033 level-ERROR    Exception on /checkState [POST]
Traceback (most recent call last):
  File "/usr/lib/python2.6/site-packages/flask/app.py", line 1982, in wsgi_app
    response = self.full_dispatch_request()
  File "/usr/lib/python2.6/site-packages/flask/app.py", line 1614, in full_dispatch_request
    rv = self.handle_user_exception(e)
  File "/usr/lib/python2.6/site-packages/flask/app.py", line 1517, in handle_user_exception
    reraise(exc_type, exc_value, tb)
  File "/usr/lib/python2.6/site-packages/flask/app.py", line 1612, in full_dispatch_request
    rv = self.dispatch_request()
  File "/usr/lib/python2.6/site-packages/flask/app.py", line 1598, in dispatch_request
    return self.view_functions[rule.endpoint](**req.view_args)
  File "/usr/lib/python2.6/site-packages/flask_login/utils.py", line 261, in decorated_view
    return func(*args, **kwargs)
  File "/data/BxcqMloms/app/decorators.py", line 8, in decorated_function
    return func(*args,**kwargs)
  File "/data/BxcqMloms/app/ywtools/views.py", line 489, in checkState
    if int(checkResultJson[xi]['code']) == 0:
KeyError: 0
2018-04-16 11:17:43,278 level-ERROR    Traceback (most recent call last):
  File "/data/BxcqMloms/app/mylibs/sendsocket.py", line 10, in send_socket
    SendSocket.connect(addr)
  File "<string>", line 1, in connect
error: [Errno 111] Connection refused

2018-04-16 11:17:43,279 level-ERROR    Traceback (most recent call last):
  File "/data/BxcqMloms/app/api/views.py", line 121, in CollectLoad
    loads = ipsLoadJson[i]['load']
KeyError: 0

2018-04-16 11:21:52,689 level-ERROR    zhengtao is logging and permission is [u'resetdate', u'sqlcommand', u'checkversion', u'gmcommand', u'closeserver', u'openserver', u'servermanager', u'displayresetversion', u'checkserverstat', u'bootgame', u'update_front', u'update_javascripts', u'update_java', u'ywupdate', u'ywtools', u'javalog', u'phplog', u'logs', u'permission', u'role', u'user', u'system', u'root']
2018-04-16 11:21:52,870 level-ERROR    AllPlatMsg is [{'gameAlias': u'bxcq', 'platformId': 2, 'platformAlias': u'qq', 'gameId': 27, 'configId': 1, 'platformName': u'qq'}, {'gameAlias': u'bxcq', 'platformId': 14, 'platformAlias': u'tencent', 'gameId': 27, 'configId': 2, 'platformName': u'tencent'}, {'gameAlias': u'bxcq', 'platformId': 15, 'platformAlias': u'108qu_rxsj', 'gameId': 27, 'configId': 3, 'platformName': u'108qu_rxsj'}, {'gameAlias': u'bxcq', 'platformId': 16, 'platformAlias': u'bengwan_rxsj', 'gameId': 27, 'configId': 4, 'platformName': u'bengwan_rxsj'}, {'gameAlias': u'bxcq', 'platformId': 17, 'platformAlias': u'354yx_rxsj', 'gameId': 27, 'configId': 5, 'platformName': u'354yx_rxsj'}, {'gameAlias': u'bxcq', 'platformId': 18, 'platformAlias': u'6344_rxsj', 'gameId': 27, 'configId': 6, 'platformName': u'6344_rxsj'}, {'gameAlias': u'bxcq', 'platformId': 19, 'platformAlias': u'mayi_rxsj', 'gameId': 27, 'configId': 7, 'platformName': u'mayi_rxsj'}, {'gameAlias': u'bxcq', 'platformId': 20, 'platformAlias': u'yaowan_rxsj', 'gameId': 27, 'configId': 8, 'platformName': u'yaowan_rxsj'}]
2018-04-16 11:25:33,336 level-ERROR    yangyang is logging and permission is [u'root', u'update_front', u'ywupdate', u'ywtools']
2018-04-16 11:25:33,534 level-ERROR    AllPlatMsg is [{'gameAlias': u'bxcq', 'platformId': 2, 'platformAlias': u'qq', 'gameId': 27, 'configId': 1, 'platformName': u'qq'}, {'gameAlias': u'bxcq', 'platformId': 14, 'platformAlias': u'tencent', 'gameId': 27, 'configId': 2, 'platformName': u'tencent'}, {'gameAlias': u'bxcq', 'platformId': 15, 'platformAlias': u'108qu_rxsj', 'gameId': 27, 'configId': 3, 'platformName': u'108qu_rxsj'}, {'gameAlias': u'bxcq', 'platformId': 16, 'platformAlias': u'bengwan_rxsj', 'gameId': 27, 'configId': 4, 'platformName': u'bengwan_rxsj'}, {'gameAlias': u'bxcq', 'platformId': 17, 'platformAlias': u'354yx_rxsj', 'gameId': 27, 'configId': 5, 'platformName': u'354yx_rxsj'}, {'gameAlias': u'bxcq', 'platformId': 18, 'platformAlias': u'6344_rxsj', 'gameId': 27, 'configId': 6, 'platformName': u'6344_rxsj'}, {'gameAlias': u'bxcq', 'platformId': 19, 'platformAlias': u'mayi_rxsj', 'gameId': 27, 'configId': 7, 'platformName': u'mayi_rxsj'}, {'gameAlias': u'bxcq', 'platformId': 20, 'platformAlias': u'yaowan_rxsj', 'gameId': 27, 'configId': 8, 'platformName': u'yaowan_rxsj'}]
2018-04-16 11:38:56,313 level-ERROR    yangyang is logging and permission is [u'root', u'update_front', u'ywupdate', u'ywtools']
2018-04-16 11:38:56,437 level-ERROR    AllPlatMsg is [{'gameAlias': u'bxcq', 'platformId': 2, 'platformAlias': u'qq', 'gameId': 27, 'configId': 1, 'platformName': u'qq'}, {'gameAlias': u'bxcq', 'platformId': 14, 'platformAlias': u'tencent', 'gameId': 27, 'configId': 2, 'platformName': u'tencent'}, {'gameAlias': u'bxcq', 'platformId': 15, 'platformAlias': u'108qu_rxsj', 'gameId': 27, 'configId': 3, 'platformName': u'108qu_rxsj'}, {'gameAlias': u'bxcq', 'platformId': 16, 'platformAlias': u'bengwan_rxsj', 'gameId': 27, 'configId': 4, 'platformName': u'bengwan_rxsj'}, {'gameAlias': u'bxcq', 'platformId': 17, 'platformAlias': u'354yx_rxsj', 'gameId': 27, 'configId': 5, 'platformName': u'354yx_rxsj'}, {'gameAlias': u'bxcq', 'platformId': 18, 'platformAlias': u'6344_rxsj', 'gameId': 27, 'configId': 6, 'platformName': u'6344_rxsj'}, {'gameAlias': u'bxcq', 'platformId': 19, 'platformAlias': u'mayi_rxsj', 'gameId': 27, 'configId': 7, 'platformName': u'mayi_rxsj'}, {'gameAlias': u'bxcq', 'platformId': 20, 'platformAlias': u'yaowan_rxsj', 'gameId': 27, 'configId': 8, 'platformName': u'yaowan_rxsj'}]
2018-04-16 16:50:41,869 level-ERROR    Traceback (most recent call last):
  File "/data/BxcqMloms/app/mylibs/sendsocket.py", line 10, in send_socket
    SendSocket.connect(addr)
  File "<string>", line 1, in connect
error: [Errno 111] Connection refused

2018-04-16 16:50:41,870 level-ERROR    Traceback (most recent call last):
  File "/data/BxcqMloms/app/api/views.py", line 121, in CollectLoad
    loads = ipsLoadJson[i]['load']
KeyError: 0

2018-04-16 16:51:16,272 level-ERROR    zhengtao is logging and permission is [u'resetdate', u'sqlcommand', u'checkversion', u'gmcommand', u'closeserver', u'openserver', u'servermanager', u'displayresetversion', u'checkserverstat', u'bootgame', u'update_front', u'update_javascripts', u'update_java', u'ywupdate', u'ywtools', u'javalog', u'phplog', u'logs', u'permission', u'role', u'user', u'system', u'root']
2018-04-16 16:51:16,410 level-ERROR    AllPlatMsg is [{'gameAlias': u'bxcq', 'platformId': 2, 'platformAlias': u'qq', 'gameId': 27, 'configId': 1, 'platformName': u'qq'}, {'gameAlias': u'bxcq', 'platformId': 14, 'platformAlias': u'tencent', 'gameId': 27, 'configId': 2, 'platformName': u'tencent'}, {'gameAlias': u'bxcq', 'platformId': 15, 'platformAlias': u'108qu_rxsj', 'gameId': 27, 'configId': 3, 'platformName': u'108qu_rxsj'}, {'gameAlias': u'bxcq', 'platformId': 16, 'platformAlias': u'bengwan_rxsj', 'gameId': 27, 'configId': 4, 'platformName': u'bengwan_rxsj'}, {'gameAlias': u'bxcq', 'platformId': 17, 'platformAlias': u'354yx_rxsj', 'gameId': 27, 'configId': 5, 'platformName': u'354yx_rxsj'}, {'gameAlias': u'bxcq', 'platformId': 18, 'platformAlias': u'6344_rxsj', 'gameId': 27, 'configId': 6, 'platformName': u'6344_rxsj'}, {'gameAlias': u'bxcq', 'platformId': 19, 'platformAlias': u'mayi_rxsj', 'gameId': 27, 'configId': 7, 'platformName': u'mayi_rxsj'}, {'gameAlias': u'bxcq', 'platformId': 20, 'platformAlias': u'yaowan_rxsj', 'gameId': 27, 'configId': 8, 'platformName': u'yaowan_rxsj'}]
2018-04-16 16:55:41,978 level-ERROR    Traceback (most recent call last):
  File "/data/BxcqMloms/app/mylibs/sendsocket.py", line 10, in send_socket
    SendSocket.connect(addr)
  File "<string>", line 1, in connect
error: [Errno 111] Connection refused

2018-04-16 16:55:41,979 level-ERROR    Traceback (most recent call last):
  File "/data/BxcqMloms/app/api/views.py", line 121, in CollectLoad
    loads = ipsLoadJson[i]['load']
KeyError: 0

2018-04-16 17:00:42,034 level-ERROR    Traceback (most recent call last):
  File "/data/BxcqMloms/app/mylibs/sendsocket.py", line 10, in send_socket
    SendSocket.connect(addr)
  File "<string>", line 1, in connect
error: [Errno 111] Connection refused

2018-04-16 17:00:42,035 level-ERROR    Traceback (most recent call last):
  File "/data/BxcqMloms/app/api/views.py", line 121, in CollectLoad
    loads = ipsLoadJson[i]['load']
KeyError: 0

2018-04-16 17:05:42,083 level-ERROR    Traceback (most recent call last):
  File "/data/BxcqMloms/app/mylibs/sendsocket.py", line 10, in send_socket
    SendSocket.connect(addr)
  File "<string>", line 1, in connect
error: [Errno 111] Connection refused

2018-04-16 17:05:42,083 level-ERROR    Traceback (most recent call last):
  File "/data/BxcqMloms/app/api/views.py", line 121, in CollectLoad
    loads = ipsLoadJson[i]['load']
KeyError: 0

2018-04-16 17:10:42,117 level-ERROR    Traceback (most recent call last):
  File "/data/BxcqMloms/app/mylibs/sendsocket.py", line 10, in send_socket
    SendSocket.connect(addr)
  File "<string>", line 1, in connect
error: [Errno 111] Connection refused

2018-04-16 17:10:42,118 level-ERROR    Traceback (most recent call last):
  File "/data/BxcqMloms/app/api/views.py", line 121, in CollectLoad
    loads = ipsLoadJson[i]['load']
KeyError: 0

2018-04-16 17:15:42,133 level-ERROR    Traceback (most recent call last):
  File "/data/BxcqMloms/app/mylibs/sendsocket.py", line 10, in send_socket
    SendSocket.connect(addr)
  File "<string>", line 1, in connect
error: [Errno 111] Connection refused

2018-04-16 17:15:42,134 level-ERROR    Traceback (most recent call last):
  File "/data/BxcqMloms/app/api/views.py", line 121, in CollectLoad
    loads = ipsLoadJson[i]['load']
KeyError: 0

2018-04-16 17:20:42,242 level-ERROR    Traceback (most recent call last):
  File "/data/BxcqMloms/app/mylibs/sendsocket.py", line 10, in send_socket
    SendSocket.connect(addr)
  File "<string>", line 1, in connect
error: [Errno 111] Connection refused

2018-04-16 17:20:42,243 level-ERROR    Traceback (most recent call last):
  File "/data/BxcqMloms/app/api/views.py", line 121, in CollectLoad
    loads = ipsLoadJson[i]['load']
KeyError: 0

2018-04-16 17:25:42,350 level-ERROR    Traceback (most recent call last):
  File "/data/BxcqMloms/app/mylibs/sendsocket.py", line 10, in send_socket
    SendSocket.connect(addr)
  File "<string>", line 1, in connect
error: [Errno 111] Connection refused

2018-04-16 17:25:42,351 level-ERROR    Traceback (most recent call last):
  File "/data/BxcqMloms/app/api/views.py", line 121, in CollectLoad
    loads = ipsLoadJson[i]['load']
KeyError: 0

2018-04-16 17:30:42,390 level-ERROR    Traceback (most recent call last):
  File "/data/BxcqMloms/app/mylibs/sendsocket.py", line 10, in send_socket
    SendSocket.connect(addr)
  File "<string>", line 1, in connect
error: [Errno 111] Connection refused

2018-04-16 17:30:42,390 level-ERROR    Traceback (most recent call last):
  File "/data/BxcqMloms/app/api/views.py", line 121, in CollectLoad
    loads = ipsLoadJson[i]['load']
KeyError: 0

2018-04-16 17:35:42,428 level-ERROR    Traceback (most recent call last):
  File "/data/BxcqMloms/app/mylibs/sendsocket.py", line 10, in send_socket
    SendSocket.connect(addr)
  File "<string>", line 1, in connect
error: [Errno 111] Connection refused

2018-04-16 17:35:42,429 level-ERROR    Traceback (most recent call last):
  File "/data/BxcqMloms/app/api/views.py", line 121, in CollectLoad
    loads = ipsLoadJson[i]['load']
KeyError: 0

2018-04-16 17:40:42,536 level-ERROR    Traceback (most recent call last):
  File "/data/BxcqMloms/app/mylibs/sendsocket.py", line 10, in send_socket
    SendSocket.connect(addr)
  File "<string>", line 1, in connect
error: [Errno 111] Connection refused

2018-04-16 17:40:42,536 level-ERROR    Traceback (most recent call last):
  File "/data/BxcqMloms/app/api/views.py", line 121, in CollectLoad
    loads = ipsLoadJson[i]['load']
KeyError: 0

2018-04-16 17:45:42,643 level-ERROR    Traceback (most recent call last):
  File "/data/BxcqMloms/app/mylibs/sendsocket.py", line 10, in send_socket
    SendSocket.connect(addr)
  File "<string>", line 1, in connect
error: [Errno 111] Connection refused

2018-04-16 17:45:42,644 level-ERROR    Traceback (most recent call last):
  File "/data/BxcqMloms/app/api/views.py", line 121, in CollectLoad
    loads = ipsLoadJson[i]['load']
KeyError: 0

2018-04-16 17:50:42,731 level-ERROR    Traceback (most recent call last):
  File "/data/BxcqMloms/app/mylibs/sendsocket.py", line 10, in send_socket
    SendSocket.connect(addr)
  File "<string>", line 1, in connect
error: [Errno 111] Connection refused

2018-04-16 17:50:42,732 level-ERROR    Traceback (most recent call last):
  File "/data/BxcqMloms/app/api/views.py", line 121, in CollectLoad
    loads = ipsLoadJson[i]['load']
KeyError: 0

2018-04-16 17:55:42,778 level-ERROR    Traceback (most recent call last):
  File "/data/BxcqMloms/app/mylibs/sendsocket.py", line 10, in send_socket
    SendSocket.connect(addr)
  File "<string>", line 1, in connect
error: [Errno 111] Connection refused

2018-04-16 17:55:42,778 level-ERROR    Traceback (most recent call last):
  File "/data/BxcqMloms/app/api/views.py", line 121, in CollectLoad
    loads = ipsLoadJson[i]['load']
KeyError: 0

2018-04-16 18:00:42,828 level-ERROR    Traceback (most recent call last):
  File "/data/BxcqMloms/app/mylibs/sendsocket.py", line 10, in send_socket
    SendSocket.connect(addr)
  File "<string>", line 1, in connect
error: [Errno 111] Connection refused

2018-04-16 18:00:42,829 level-ERROR    Traceback (most recent call last):
  File "/data/BxcqMloms/app/api/views.py", line 121, in CollectLoad
    loads = ipsLoadJson[i]['load']
KeyError: 0

2018-04-16 18:05:42,936 level-ERROR    Traceback (most recent call last):
  File "/data/BxcqMloms/app/mylibs/sendsocket.py", line 10, in send_socket
    SendSocket.connect(addr)
  File "<string>", line 1, in connect
error: [Errno 111] Connection refused

2018-04-16 18:05:42,937 level-ERROR    Traceback (most recent call last):
  File "/data/BxcqMloms/app/api/views.py", line 121, in CollectLoad
    loads = ipsLoadJson[i]['load']
KeyError: 0

2018-04-16 18:10:42,979 level-ERROR    Traceback (most recent call last):
  File "/data/BxcqMloms/app/mylibs/sendsocket.py", line 10, in send_socket
    SendSocket.connect(addr)
  File "<string>", line 1, in connect
error: [Errno 111] Connection refused

2018-04-16 18:10:42,980 level-ERROR    Traceback (most recent call last):
  File "/data/BxcqMloms/app/api/views.py", line 121, in CollectLoad
    loads = ipsLoadJson[i]['load']
KeyError: 0

2018-04-16 18:15:43,087 level-ERROR    Traceback (most recent call last):
  File "/data/BxcqMloms/app/mylibs/sendsocket.py", line 10, in send_socket
    SendSocket.connect(addr)
  File "<string>", line 1, in connect
error: [Errno 111] Connection refused

2018-04-16 18:15:43,088 level-ERROR    Traceback (most recent call last):
  File "/data/BxcqMloms/app/api/views.py", line 121, in CollectLoad
    loads = ipsLoadJson[i]['load']
KeyError: 0

2018-04-16 18:20:43,130 level-ERROR    Traceback (most recent call last):
  File "/data/BxcqMloms/app/mylibs/sendsocket.py", line 10, in send_socket
    SendSocket.connect(addr)
  File "<string>", line 1, in connect
error: [Errno 111] Connection refused

2018-04-16 18:20:43,130 level-ERROR    Traceback (most recent call last):
  File "/data/BxcqMloms/app/api/views.py", line 121, in CollectLoad
    loads = ipsLoadJson[i]['load']
KeyError: 0

2018-04-16 18:25:43,229 level-ERROR    Traceback (most recent call last):
  File "/data/BxcqMloms/app/mylibs/sendsocket.py", line 10, in send_socket
    SendSocket.connect(addr)
  File "<string>", line 1, in connect
error: [Errno 111] Connection refused

2018-04-16 18:25:43,229 level-ERROR    Traceback (most recent call last):
  File "/data/BxcqMloms/app/api/views.py", line 121, in CollectLoad
    loads = ipsLoadJson[i]['load']
KeyError: 0

2018-04-16 18:30:43,278 level-ERROR    Traceback (most recent call last):
  File "/data/BxcqMloms/app/mylibs/sendsocket.py", line 10, in send_socket
    SendSocket.connect(addr)
  File "<string>", line 1, in connect
error: [Errno 111] Connection refused

2018-04-16 18:30:43,279 level-ERROR    Traceback (most recent call last):
  File "/data/BxcqMloms/app/api/views.py", line 121, in CollectLoad
    loads = ipsLoadJson[i]['load']
KeyError: 0

2018-04-16 18:35:43,329 level-ERROR    Traceback (most recent call last):
  File "/data/BxcqMloms/app/mylibs/sendsocket.py", line 10, in send_socket
    SendSocket.connect(addr)
  File "<string>", line 1, in connect
error: [Errno 111] Connection refused

2018-04-16 18:35:43,329 level-ERROR    Traceback (most recent call last):
  File "/data/BxcqMloms/app/api/views.py", line 121, in CollectLoad
    loads = ipsLoadJson[i]['load']
KeyError: 0

2018-04-16 18:40:43,423 level-ERROR    Traceback (most recent call last):
  File "/data/BxcqMloms/app/mylibs/sendsocket.py", line 10, in send_socket
    SendSocket.connect(addr)
  File "<string>", line 1, in connect
error: [Errno 111] Connection refused

2018-04-16 18:40:43,424 level-ERROR    Traceback (most recent call last):
  File "/data/BxcqMloms/app/api/views.py", line 121, in CollectLoad
    loads = ipsLoadJson[i]['load']
KeyError: 0

2018-04-16 18:45:43,479 level-ERROR    Traceback (most recent call last):
  File "/data/BxcqMloms/app/mylibs/sendsocket.py", line 10, in send_socket
    SendSocket.connect(addr)
  File "<string>", line 1, in connect
error: [Errno 111] Connection refused

2018-04-16 18:45:43,480 level-ERROR    Traceback (most recent call last):
  File "/data/BxcqMloms/app/api/views.py", line 121, in CollectLoad
    loads = ipsLoadJson[i]['load']
KeyError: 0

2018-04-16 18:50:43,586 level-ERROR    Traceback (most recent call last):
  File "/data/BxcqMloms/app/mylibs/sendsocket.py", line 10, in send_socket
    SendSocket.connect(addr)
  File "<string>", line 1, in connect
error: [Errno 111] Connection refused

2018-04-16 18:50:43,587 level-ERROR    Traceback (most recent call last):
  File "/data/BxcqMloms/app/api/views.py", line 121, in CollectLoad
    loads = ipsLoadJson[i]['load']
KeyError: 0

2018-04-16 18:55:43,694 level-ERROR    Traceback (most recent call last):
  File "/data/BxcqMloms/app/mylibs/sendsocket.py", line 10, in send_socket
    SendSocket.connect(addr)
  File "<string>", line 1, in connect
error: [Errno 111] Connection refused

2018-04-16 18:55:43,694 level-ERROR    Traceback (most recent call last):
  File "/data/BxcqMloms/app/api/views.py", line 121, in CollectLoad
    loads = ipsLoadJson[i]['load']
KeyError: 0

2018-04-16 19:00:43,846 level-ERROR    Traceback (most recent call last):
  File "/data/BxcqMloms/app/mylibs/sendsocket.py", line 10, in send_socket
    SendSocket.connect(addr)
  File "<string>", line 1, in connect
error: [Errno 111] Connection refused

2018-04-16 19:00:43,846 level-ERROR    Traceback (most recent call last):
  File "/data/BxcqMloms/app/api/views.py", line 121, in CollectLoad
    loads = ipsLoadJson[i]['load']
KeyError: 0

2018-04-16 19:05:43,880 level-ERROR    Traceback (most recent call last):
  File "/data/BxcqMloms/app/mylibs/sendsocket.py", line 10, in send_socket
    SendSocket.connect(addr)
  File "<string>", line 1, in connect
error: [Errno 111] Connection refused

2018-04-16 19:05:43,881 level-ERROR    Traceback (most recent call last):
  File "/data/BxcqMloms/app/api/views.py", line 121, in CollectLoad
    loads = ipsLoadJson[i]['load']
KeyError: 0

2018-04-16 19:10:43,989 level-ERROR    Traceback (most recent call last):
  File "/data/BxcqMloms/app/mylibs/sendsocket.py", line 10, in send_socket
    SendSocket.connect(addr)
  File "<string>", line 1, in connect
error: [Errno 111] Connection refused

2018-04-16 19:10:43,989 level-ERROR    Traceback (most recent call last):
  File "/data/BxcqMloms/app/api/views.py", line 121, in CollectLoad
    loads = ipsLoadJson[i]['load']
KeyError: 0

2018-04-16 19:15:44,097 level-ERROR    Traceback (most recent call last):
  File "/data/BxcqMloms/app/mylibs/sendsocket.py", line 10, in send_socket
    SendSocket.connect(addr)
  File "<string>", line 1, in connect
error: [Errno 111] Connection refused

2018-04-16 19:15:44,097 level-ERROR    Traceback (most recent call last):
  File "/data/BxcqMloms/app/api/views.py", line 121, in CollectLoad
    loads = ipsLoadJson[i]['load']
KeyError: 0

2018-04-16 19:20:44,205 level-ERROR    Traceback (most recent call last):
  File "/data/BxcqMloms/app/mylibs/sendsocket.py", line 10, in send_socket
    SendSocket.connect(addr)
  File "<string>", line 1, in connect
error: [Errno 111] Connection refused

2018-04-16 19:20:44,205 level-ERROR    Traceback (most recent call last):
  File "/data/BxcqMloms/app/api/views.py", line 121, in CollectLoad
    loads = ipsLoadJson[i]['load']
KeyError: 0

2018-04-16 19:25:44,312 level-ERROR    Traceback (most recent call last):
  File "/data/BxcqMloms/app/mylibs/sendsocket.py", line 10, in send_socket
    SendSocket.connect(addr)
  File "<string>", line 1, in connect
error: [Errno 111] Connection refused

2018-04-16 19:25:44,312 level-ERROR    Traceback (most recent call last):
  File "/data/BxcqMloms/app/api/views.py", line 121, in CollectLoad
    loads = ipsLoadJson[i]['load']
KeyError: 0

2018-04-16 19:30:44,418 level-ERROR    Traceback (most recent call last):
  File "/data/BxcqMloms/app/mylibs/sendsocket.py", line 10, in send_socket
    SendSocket.connect(addr)
  File "<string>", line 1, in connect
error: [Errno 111] Connection refused

2018-04-16 19:30:44,419 level-ERROR    Traceback (most recent call last):
  File "/data/BxcqMloms/app/api/views.py", line 121, in CollectLoad
    loads = ipsLoadJson[i]['load']
KeyError: 0

2018-04-16 19:35:44,527 level-ERROR    Traceback (most recent call last):
  File "/data/BxcqMloms/app/mylibs/sendsocket.py", line 10, in send_socket
    SendSocket.connect(addr)
  File "<string>", line 1, in connect
error: [Errno 111] Connection refused

2018-04-16 19:35:44,527 level-ERROR    Traceback (most recent call last):
  File "/data/BxcqMloms/app/api/views.py", line 121, in CollectLoad
    loads = ipsLoadJson[i]['load']
KeyError: 0

2018-04-16 19:40:44,627 level-ERROR    Traceback (most recent call last):
  File "/data/BxcqMloms/app/mylibs/sendsocket.py", line 10, in send_socket
    SendSocket.connect(addr)
  File "<string>", line 1, in connect
error: [Errno 111] Connection refused

2018-04-16 19:40:44,627 level-ERROR    Traceback (most recent call last):
  File "/data/BxcqMloms/app/api/views.py", line 121, in CollectLoad
    loads = ipsLoadJson[i]['load']
KeyError: 0

2018-04-16 19:45:44,703 level-ERROR    Traceback (most recent call last):
  File "/data/BxcqMloms/app/mylibs/sendsocket.py", line 10, in send_socket
    SendSocket.connect(addr)
  File "<string>", line 1, in connect
error: [Errno 111] Connection refused

2018-04-16 19:45:44,704 level-ERROR    Traceback (most recent call last):
  File "/data/BxcqMloms/app/api/views.py", line 121, in CollectLoad
    loads = ipsLoadJson[i]['load']
KeyError: 0

2018-04-16 19:50:44,764 level-ERROR    Traceback (most recent call last):
  File "/data/BxcqMloms/app/mylibs/sendsocket.py", line 10, in send_socket
    SendSocket.connect(addr)
  File "<string>", line 1, in connect
error: [Errno 111] Connection refused

2018-04-16 19:50:44,764 level-ERROR    Traceback (most recent call last):
  File "/data/BxcqMloms/app/api/views.py", line 121, in CollectLoad
    loads = ipsLoadJson[i]['load']
KeyError: 0

2018-04-16 19:55:44,777 level-ERROR    Traceback (most recent call last):
  File "/data/BxcqMloms/app/mylibs/sendsocket.py", line 10, in send_socket
    SendSocket.connect(addr)
  File "<string>", line 1, in connect
error: [Errno 111] Connection refused

2018-04-16 19:55:44,778 level-ERROR    Traceback (most recent call last):
  File "/data/BxcqMloms/app/api/views.py", line 121, in CollectLoad
    loads = ipsLoadJson[i]['load']
KeyError: 0

2018-04-16 20:00:44,827 level-ERROR    Traceback (most recent call last):
  File "/data/BxcqMloms/app/mylibs/sendsocket.py", line 10, in send_socket
    SendSocket.connect(addr)
  File "<string>", line 1, in connect
error: [Errno 111] Connection refused

2018-04-16 20:00:44,827 level-ERROR    Traceback (most recent call last):
  File "/data/BxcqMloms/app/api/views.py", line 121, in CollectLoad
    loads = ipsLoadJson[i]['load']
KeyError: 0

2018-04-16 20:05:44,921 level-ERROR    Traceback (most recent call last):
  File "/data/BxcqMloms/app/mylibs/sendsocket.py", line 10, in send_socket
    SendSocket.connect(addr)
  File "<string>", line 1, in connect
error: [Errno 111] Connection refused

2018-04-16 20:05:44,921 level-ERROR    Traceback (most recent call last):
  File "/data/BxcqMloms/app/api/views.py", line 121, in CollectLoad
    loads = ipsLoadJson[i]['load']
KeyError: 0

2018-04-16 20:10:44,978 level-ERROR    Traceback (most recent call last):
  File "/data/BxcqMloms/app/mylibs/sendsocket.py", line 10, in send_socket
    SendSocket.connect(addr)
  File "<string>", line 1, in connect
error: [Errno 111] Connection refused

2018-04-16 20:10:44,979 level-ERROR    Traceback (most recent call last):
  File "/data/BxcqMloms/app/api/views.py", line 121, in CollectLoad
    loads = ipsLoadJson[i]['load']
KeyError: 0

2018-04-16 20:15:45,027 level-ERROR    Traceback (most recent call last):
  File "/data/BxcqMloms/app/mylibs/sendsocket.py", line 10, in send_socket
    SendSocket.connect(addr)
  File "<string>", line 1, in connect
error: [Errno 111] Connection refused

2018-04-16 20:15:45,028 level-ERROR    Traceback (most recent call last):
  File "/data/BxcqMloms/app/api/views.py", line 121, in CollectLoad
    loads = ipsLoadJson[i]['load']
KeyError: 0

2018-04-16 20:20:45,127 level-ERROR    Traceback (most recent call last):
  File "/data/BxcqMloms/app/mylibs/sendsocket.py", line 10, in send_socket
    SendSocket.connect(addr)
  File "<string>", line 1, in connect
error: [Errno 111] Connection refused

2018-04-16 20:20:45,127 level-ERROR    Traceback (most recent call last):
  File "/data/BxcqMloms/app/api/views.py", line 121, in CollectLoad
    loads = ipsLoadJson[i]['load']
KeyError: 0

2018-04-16 20:25:45,234 level-ERROR    Traceback (most recent call last):
  File "/data/BxcqMloms/app/mylibs/sendsocket.py", line 10, in send_socket
    SendSocket.connect(addr)
  File "<string>", line 1, in connect
error: [Errno 111] Connection refused

2018-04-16 20:25:45,235 level-ERROR    Traceback (most recent call last):
  File "/data/BxcqMloms/app/api/views.py", line 121, in CollectLoad
    loads = ipsLoadJson[i]['load']
KeyError: 0

2018-04-16 20:30:45,313 level-ERROR    Traceback (most recent call last):
  File "/data/BxcqMloms/app/mylibs/sendsocket.py", line 10, in send_socket
    SendSocket.connect(addr)
  File "<string>", line 1, in connect
error: [Errno 111] Connection refused

2018-04-16 20:30:45,313 level-ERROR    Traceback (most recent call last):
  File "/data/BxcqMloms/app/api/views.py", line 121, in CollectLoad
    loads = ipsLoadJson[i]['load']
KeyError: 0

2018-04-16 20:35:45,337 level-ERROR    Traceback (most recent call last):
  File "/data/BxcqMloms/app/mylibs/sendsocket.py", line 10, in send_socket
    SendSocket.connect(addr)
  File "<string>", line 1, in connect
error: [Errno 111] Connection refused

2018-04-16 20:35:45,338 level-ERROR    Traceback (most recent call last):
  File "/data/BxcqMloms/app/api/views.py", line 121, in CollectLoad
    loads = ipsLoadJson[i]['load']
KeyError: 0

2018-04-16 20:40:45,446 level-ERROR    Traceback (most recent call last):
  File "/data/BxcqMloms/app/mylibs/sendsocket.py", line 10, in send_socket
    SendSocket.connect(addr)
  File "<string>", line 1, in connect
error: [Errno 111] Connection refused

2018-04-16 20:40:45,446 level-ERROR    Traceback (most recent call last):
  File "/data/BxcqMloms/app/api/views.py", line 121, in CollectLoad
    loads = ipsLoadJson[i]['load']
KeyError: 0

2018-04-16 20:45:45,554 level-ERROR    Traceback (most recent call last):
  File "/data/BxcqMloms/app/mylibs/sendsocket.py", line 10, in send_socket
    SendSocket.connect(addr)
  File "<string>", line 1, in connect
error: [Errno 111] Connection refused

2018-04-16 20:45:45,554 level-ERROR    Traceback (most recent call last):
  File "/data/BxcqMloms/app/api/views.py", line 121, in CollectLoad
    loads = ipsLoadJson[i]['load']
KeyError: 0

2018-04-16 20:50:45,662 level-ERROR    Traceback (most recent call last):
  File "/data/BxcqMloms/app/mylibs/sendsocket.py", line 10, in send_socket
    SendSocket.connect(addr)
  File "<string>", line 1, in connect
error: [Errno 111] Connection refused

2018-04-16 20:50:45,663 level-ERROR    Traceback (most recent call last):
  File "/data/BxcqMloms/app/api/views.py", line 121, in CollectLoad
    loads = ipsLoadJson[i]['load']
KeyError: 0

2018-04-16 20:55:45,739 level-ERROR    Traceback (most recent call last):
  File "/data/BxcqMloms/app/mylibs/sendsocket.py", line 10, in send_socket
    SendSocket.connect(addr)
  File "<string>", line 1, in connect
error: [Errno 111] Connection refused

2018-04-16 20:55:45,740 level-ERROR    Traceback (most recent call last):
  File "/data/BxcqMloms/app/api/views.py", line 121, in CollectLoad
    loads = ipsLoadJson[i]['load']
KeyError: 0

2018-04-16 21:00:45,780 level-ERROR    Traceback (most recent call last):
  File "/data/BxcqMloms/app/mylibs/sendsocket.py", line 10, in send_socket
    SendSocket.connect(addr)
  File "<string>", line 1, in connect
error: [Errno 111] Connection refused

2018-04-16 21:00:45,780 level-ERROR    Traceback (most recent call last):
  File "/data/BxcqMloms/app/api/views.py", line 121, in CollectLoad
    loads = ipsLoadJson[i]['load']
KeyError: 0

2018-04-16 21:05:45,792 level-ERROR    Traceback (most recent call last):
  File "/data/BxcqMloms/app/mylibs/sendsocket.py", line 10, in send_socket
    SendSocket.connect(addr)
  File "<string>", line 1, in connect
error: [Errno 111] Connection refused

2018-04-16 21:05:45,793 level-ERROR    Traceback (most recent call last):
  File "/data/BxcqMloms/app/api/views.py", line 121, in CollectLoad
    loads = ipsLoadJson[i]['load']
KeyError: 0

2018-04-16 21:10:45,874 level-ERROR    Traceback (most recent call last):
  File "/data/BxcqMloms/app/mylibs/sendsocket.py", line 10, in send_socket
    SendSocket.connect(addr)
  File "<string>", line 1, in connect
error: [Errno 111] Connection refused

2018-04-16 21:10:45,874 level-ERROR    Traceback (most recent call last):
  File "/data/BxcqMloms/app/api/views.py", line 121, in CollectLoad
    loads = ipsLoadJson[i]['load']
KeyError: 0

2018-04-16 21:15:45,931 level-ERROR    Traceback (most recent call last):
  File "/data/BxcqMloms/app/mylibs/sendsocket.py", line 10, in send_socket
    SendSocket.connect(addr)
  File "<string>", line 1, in connect
error: [Errno 111] Connection refused

2018-04-16 21:15:45,931 level-ERROR    Traceback (most recent call last):
  File "/data/BxcqMloms/app/api/views.py", line 121, in CollectLoad
    loads = ipsLoadJson[i]['load']
KeyError: 0

2018-04-16 21:20:46,039 level-ERROR    Traceback (most recent call last):
  File "/data/BxcqMloms/app/mylibs/sendsocket.py", line 10, in send_socket
    SendSocket.connect(addr)
  File "<string>", line 1, in connect
error: [Errno 111] Connection refused

2018-04-16 21:20:46,039 level-ERROR    Traceback (most recent call last):
  File "/data/BxcqMloms/app/api/views.py", line 121, in CollectLoad
    loads = ipsLoadJson[i]['load']
KeyError: 0

2018-04-16 21:25:46,135 level-ERROR    Traceback (most recent call last):
  File "/data/BxcqMloms/app/mylibs/sendsocket.py", line 10, in send_socket
    SendSocket.connect(addr)
  File "<string>", line 1, in connect
error: [Errno 111] Connection refused

2018-04-16 21:25:46,135 level-ERROR    Traceback (most recent call last):
  File "/data/BxcqMloms/app/api/views.py", line 121, in CollectLoad
    loads = ipsLoadJson[i]['load']
KeyError: 0

2018-04-16 21:30:46,183 level-ERROR    Traceback (most recent call last):
  File "/data/BxcqMloms/app/mylibs/sendsocket.py", line 10, in send_socket
    SendSocket.connect(addr)
  File "<string>", line 1, in connect
error: [Errno 111] Connection refused

2018-04-16 21:30:46,183 level-ERROR    Traceback (most recent call last):
  File "/data/BxcqMloms/app/api/views.py", line 121, in CollectLoad
    loads = ipsLoadJson[i]['load']
KeyError: 0

2018-04-16 21:35:46,290 level-ERROR    Traceback (most recent call last):
  File "/data/BxcqMloms/app/mylibs/sendsocket.py", line 10, in send_socket
    SendSocket.connect(addr)
  File "<string>", line 1, in connect
error: [Errno 111] Connection refused

2018-04-16 21:35:46,291 level-ERROR    Traceback (most recent call last):
  File "/data/BxcqMloms/app/api/views.py", line 121, in CollectLoad
    loads = ipsLoadJson[i]['load']
KeyError: 0

2018-04-16 21:40:46,397 level-ERROR    Traceback (most recent call last):
  File "/data/BxcqMloms/app/mylibs/sendsocket.py", line 10, in send_socket
    SendSocket.connect(addr)
  File "<string>", line 1, in connect
error: [Errno 111] Connection refused

2018-04-16 21:40:46,398 level-ERROR    Traceback (most recent call last):
  File "/data/BxcqMloms/app/api/views.py", line 121, in CollectLoad
    loads = ipsLoadJson[i]['load']
KeyError: 0

2018-04-16 21:45:46,482 level-ERROR    Traceback (most recent call last):
  File "/data/BxcqMloms/app/mylibs/sendsocket.py", line 10, in send_socket
    SendSocket.connect(addr)
  File "<string>", line 1, in connect
error: [Errno 111] Connection refused

2018-04-16 21:45:46,483 level-ERROR    Traceback (most recent call last):
  File "/data/BxcqMloms/app/api/views.py", line 121, in CollectLoad
    loads = ipsLoadJson[i]['load']
KeyError: 0

2018-04-16 21:50:46,589 level-ERROR    Traceback (most recent call last):
  File "/data/BxcqMloms/app/mylibs/sendsocket.py", line 10, in send_socket
    SendSocket.connect(addr)
  File "<string>", line 1, in connect
error: [Errno 111] Connection refused

2018-04-16 21:50:46,589 level-ERROR    Traceback (most recent call last):
  File "/data/BxcqMloms/app/api/views.py", line 121, in CollectLoad
    loads = ipsLoadJson[i]['load']
KeyError: 0

2018-04-16 21:55:46,645 level-ERROR    Traceback (most recent call last):
  File "/data/BxcqMloms/app/mylibs/sendsocket.py", line 10, in send_socket
    SendSocket.connect(addr)
  File "<string>", line 1, in connect
error: [Errno 111] Connection refused

2018-04-16 21:55:46,646 level-ERROR    Traceback (most recent call last):
  File "/data/BxcqMloms/app/api/views.py", line 121, in CollectLoad
    loads = ipsLoadJson[i]['load']
KeyError: 0

2018-04-16 22:00:46,754 level-ERROR    Traceback (most recent call last):
  File "/data/BxcqMloms/app/mylibs/sendsocket.py", line 10, in send_socket
    SendSocket.connect(addr)
  File "<string>", line 1, in connect
error: [Errno 111] Connection refused

2018-04-16 22:00:46,754 level-ERROR    Traceback (most recent call last):
  File "/data/BxcqMloms/app/api/views.py", line 121, in CollectLoad
    loads = ipsLoadJson[i]['load']
KeyError: 0

2018-04-16 22:05:46,821 level-ERROR    Traceback (most recent call last):
  File "/data/BxcqMloms/app/mylibs/sendsocket.py", line 10, in send_socket
    SendSocket.connect(addr)
  File "<string>", line 1, in connect
error: [Errno 111] Connection refused

2018-04-16 22:05:46,822 level-ERROR    Traceback (most recent call last):
  File "/data/BxcqMloms/app/api/views.py", line 121, in CollectLoad
    loads = ipsLoadJson[i]['load']
KeyError: 0

2018-04-16 22:10:46,867 level-ERROR    Traceback (most recent call last):
  File "/data/BxcqMloms/app/mylibs/sendsocket.py", line 10, in send_socket
    SendSocket.connect(addr)
  File "<string>", line 1, in connect
error: [Errno 111] Connection refused

2018-04-16 22:10:46,868 level-ERROR    Traceback (most recent call last):
  File "/data/BxcqMloms/app/api/views.py", line 121, in CollectLoad
    loads = ipsLoadJson[i]['load']
KeyError: 0

2018-04-16 22:15:46,884 level-ERROR    Traceback (most recent call last):
  File "/data/BxcqMloms/app/mylibs/sendsocket.py", line 10, in send_socket
    SendSocket.connect(addr)
  File "<string>", line 1, in connect
error: [Errno 111] Connection refused

2018-04-16 22:15:46,884 level-ERROR    Traceback (most recent call last):
  File "/data/BxcqMloms/app/api/views.py", line 121, in CollectLoad
    loads = ipsLoadJson[i]['load']
KeyError: 0

2018-04-16 22:20:46,991 level-ERROR    Traceback (most recent call last):
  File "/data/BxcqMloms/app/mylibs/sendsocket.py", line 10, in send_socket
    SendSocket.connect(addr)
  File "<string>", line 1, in connect
error: [Errno 111] Connection refused

2018-04-16 22:20:46,991 level-ERROR    Traceback (most recent call last):
  File "/data/BxcqMloms/app/api/views.py", line 121, in CollectLoad
    loads = ipsLoadJson[i]['load']
KeyError: 0

2018-04-16 22:25:47,098 level-ERROR    Traceback (most recent call last):
  File "/data/BxcqMloms/app/mylibs/sendsocket.py", line 10, in send_socket
    SendSocket.connect(addr)
  File "<string>", line 1, in connect
error: [Errno 111] Connection refused

2018-04-16 22:25:47,099 level-ERROR    Traceback (most recent call last):
  File "/data/BxcqMloms/app/api/views.py", line 121, in CollectLoad
    loads = ipsLoadJson[i]['load']
KeyError: 0

2018-04-16 22:30:47,134 level-ERROR    Traceback (most recent call last):
  File "/data/BxcqMloms/app/mylibs/sendsocket.py", line 10, in send_socket
    SendSocket.connect(addr)
  File "<string>", line 1, in connect
error: [Errno 111] Connection refused

2018-04-16 22:30:47,135 level-ERROR    Traceback (most recent call last):
  File "/data/BxcqMloms/app/api/views.py", line 121, in CollectLoad
    loads = ipsLoadJson[i]['load']
KeyError: 0

2018-04-16 22:35:47,246 level-ERROR    Traceback (most recent call last):
  File "/data/BxcqMloms/app/mylibs/sendsocket.py", line 10, in send_socket
    SendSocket.connect(addr)
  File "<string>", line 1, in connect
error: [Errno 111] Connection refused

2018-04-16 22:35:47,247 level-ERROR    Traceback (most recent call last):
  File "/data/BxcqMloms/app/api/views.py", line 121, in CollectLoad
    loads = ipsLoadJson[i]['load']
KeyError: 0

2018-04-16 22:40:47,354 level-ERROR    Traceback (most recent call last):
  File "/data/BxcqMloms/app/mylibs/sendsocket.py", line 10, in send_socket
    SendSocket.connect(addr)
  File "<string>", line 1, in connect
error: [Errno 111] Connection refused

2018-04-16 22:40:47,355 level-ERROR    Traceback (most recent call last):
  File "/data/BxcqMloms/app/api/views.py", line 121, in CollectLoad
    loads = ipsLoadJson[i]['load']
KeyError: 0

2018-04-16 22:45:47,462 level-ERROR    Traceback (most recent call last):
  File "/data/BxcqMloms/app/mylibs/sendsocket.py", line 10, in send_socket
    SendSocket.connect(addr)
  File "<string>", line 1, in connect
error: [Errno 111] Connection refused

2018-04-16 22:45:47,463 level-ERROR    Traceback (most recent call last):
  File "/data/BxcqMloms/app/api/views.py", line 121, in CollectLoad
    loads = ipsLoadJson[i]['load']
KeyError: 0

2018-04-16 22:50:47,572 level-ERROR    Traceback (most recent call last):
  File "/data/BxcqMloms/app/mylibs/sendsocket.py", line 10, in send_socket
    SendSocket.connect(addr)
  File "<string>", line 1, in connect
error: [Errno 111] Connection refused

2018-04-16 22:50:47,572 level-ERROR    Traceback (most recent call last):
  File "/data/BxcqMloms/app/api/views.py", line 121, in CollectLoad
    loads = ipsLoadJson[i]['load']
KeyError: 0

2018-04-16 22:55:47,660 level-ERROR    Traceback (most recent call last):
  File "/data/BxcqMloms/app/mylibs/sendsocket.py", line 10, in send_socket
    SendSocket.connect(addr)
  File "<string>", line 1, in connect
error: [Errno 111] Connection refused

2018-04-16 22:55:47,661 level-ERROR    Traceback (most recent call last):
  File "/data/BxcqMloms/app/api/views.py", line 121, in CollectLoad
    loads = ipsLoadJson[i]['load']
KeyError: 0

2018-04-16 23:00:47,687 level-ERROR    Traceback (most recent call last):
  File "/data/BxcqMloms/app/mylibs/sendsocket.py", line 10, in send_socket
    SendSocket.connect(addr)
  File "<string>", line 1, in connect
error: [Errno 111] Connection refused

2018-04-16 23:00:47,688 level-ERROR    Traceback (most recent call last):
  File "/data/BxcqMloms/app/api/views.py", line 121, in CollectLoad
    loads = ipsLoadJson[i]['load']
KeyError: 0

2018-04-16 23:05:47,795 level-ERROR    Traceback (most recent call last):
  File "/data/BxcqMloms/app/mylibs/sendsocket.py", line 10, in send_socket
    SendSocket.connect(addr)
  File "<string>", line 1, in connect
error: [Errno 111] Connection refused

2018-04-16 23:05:47,796 level-ERROR    Traceback (most recent call last):
  File "/data/BxcqMloms/app/api/views.py", line 121, in CollectLoad
    loads = ipsLoadJson[i]['load']
KeyError: 0

2018-04-16 23:10:47,872 level-ERROR    Traceback (most recent call last):
  File "/data/BxcqMloms/app/mylibs/sendsocket.py", line 10, in send_socket
    SendSocket.connect(addr)
  File "<string>", line 1, in connect
error: [Errno 111] Connection refused

2018-04-16 23:10:47,873 level-ERROR    Traceback (most recent call last):
  File "/data/BxcqMloms/app/api/views.py", line 121, in CollectLoad
    loads = ipsLoadJson[i]['load']
KeyError: 0

2018-04-16 23:15:47,980 level-ERROR    Traceback (most recent call last):
  File "/data/BxcqMloms/app/mylibs/sendsocket.py", line 10, in send_socket
    SendSocket.connect(addr)
  File "<string>", line 1, in connect
error: [Errno 111] Connection refused

2018-04-16 23:15:47,981 level-ERROR    Traceback (most recent call last):
  File "/data/BxcqMloms/app/api/views.py", line 121, in CollectLoad
    loads = ipsLoadJson[i]['load']
KeyError: 0

2018-04-16 23:20:48,088 level-ERROR    Traceback (most recent call last):
  File "/data/BxcqMloms/app/mylibs/sendsocket.py", line 10, in send_socket
    SendSocket.connect(addr)
  File "<string>", line 1, in connect
error: [Errno 111] Connection refused

2018-04-16 23:20:48,088 level-ERROR    Traceback (most recent call last):
  File "/data/BxcqMloms/app/api/views.py", line 121, in CollectLoad
    loads = ipsLoadJson[i]['load']
KeyError: 0

2018-04-16 23:25:48,170 level-ERROR    Traceback (most recent call last):
  File "/data/BxcqMloms/app/mylibs/sendsocket.py", line 10, in send_socket
    SendSocket.connect(addr)
  File "<string>", line 1, in connect
error: [Errno 111] Connection refused

2018-04-16 23:25:48,171 level-ERROR    Traceback (most recent call last):
  File "/data/BxcqMloms/app/api/views.py", line 121, in CollectLoad
    loads = ipsLoadJson[i]['load']
KeyError: 0

2018-04-16 23:30:48,278 level-ERROR    Traceback (most recent call last):
  File "/data/BxcqMloms/app/mylibs/sendsocket.py", line 10, in send_socket
    SendSocket.connect(addr)
  File "<string>", line 1, in connect
error: [Errno 111] Connection refused

2018-04-16 23:30:48,278 level-ERROR    Traceback (most recent call last):
  File "/data/BxcqMloms/app/api/views.py", line 121, in CollectLoad
    loads = ipsLoadJson[i]['load']
KeyError: 0

2018-04-16 23:35:48,343 level-ERROR    Traceback (most recent call last):
  File "/data/BxcqMloms/app/mylibs/sendsocket.py", line 10, in send_socket
    SendSocket.connect(addr)
  File "<string>", line 1, in connect
error: [Errno 111] Connection refused

2018-04-16 23:35:48,344 level-ERROR    Traceback (most recent call last):
  File "/data/BxcqMloms/app/api/views.py", line 121, in CollectLoad
    loads = ipsLoadJson[i]['load']
KeyError: 0

2018-04-16 23:40:48,453 level-ERROR    Traceback (most recent call last):
  File "/data/BxcqMloms/app/mylibs/sendsocket.py", line 10, in send_socket
    SendSocket.connect(addr)
  File "<string>", line 1, in connect
error: [Errno 111] Connection refused

2018-04-16 23:40:48,454 level-ERROR    Traceback (most recent call last):
  File "/data/BxcqMloms/app/api/views.py", line 121, in CollectLoad
    loads = ipsLoadJson[i]['load']
KeyError: 0

2018-04-16 23:45:48,562 level-ERROR    Traceback (most recent call last):
  File "/data/BxcqMloms/app/mylibs/sendsocket.py", line 10, in send_socket
    SendSocket.connect(addr)
  File "<string>", line 1, in connect
error: [Errno 111] Connection refused

2018-04-16 23:45:48,564 level-ERROR    Traceback (most recent call last):
  File "/data/BxcqMloms/app/api/views.py", line 121, in CollectLoad
    loads = ipsLoadJson[i]['load']
KeyError: 0

2018-04-16 23:50:48,672 level-ERROR    Traceback (most recent call last):
  File "/data/BxcqMloms/app/mylibs/sendsocket.py", line 10, in send_socket
    SendSocket.connect(addr)
  File "<string>", line 1, in connect
error: [Errno 111] Connection refused

2018-04-16 23:50:48,672 level-ERROR    Traceback (most recent call last):
  File "/data/BxcqMloms/app/api/views.py", line 121, in CollectLoad
    loads = ipsLoadJson[i]['load']
KeyError: 0

2018-04-16 23:55:48,684 level-ERROR    Traceback (most recent call last):
  File "/data/BxcqMloms/app/mylibs/sendsocket.py", line 10, in send_socket
    SendSocket.connect(addr)
  File "<string>", line 1, in connect
error: [Errno 111] Connection refused

2018-04-16 23:55:48,684 level-ERROR    Traceback (most recent call last):
  File "/data/BxcqMloms/app/api/views.py", line 121, in CollectLoad
    loads = ipsLoadJson[i]['load']
KeyError: 0

