2019-03-01 11:13:04,531 level-ERROR    Exception on /ding [GET]
Traceback (most recent call last):
  File "/usr/lib/python2.6/site-packages/flask/app.py", line 1982, in wsgi_app
    response = self.full_dispatch_request()
  File "/usr/lib/python2.6/site-packages/flask/app.py", line 1614, in full_dispatch_request
    rv = self.handle_user_exception(e)
  File "/usr/lib/python2.6/site-packages/flask/app.py", line 1517, in handle_user_exception
    reraise(exc_type, exc_value, tb)
  File "/usr/lib/python2.6/site-packages/flask/app.py", line 1612, in full_dispatch_request
    rv = self.dispatch_request()
  File "/usr/lib/python2.6/site-packages/flask/app.py", line 1598, in dispatch_request
    return self.view_functions[rule.endpoint](**req.view_args)
  File "/data/BxcqMloms/app/main/views.py", line 59, in infoindex
    username = request.get["name"]
  File "/usr/lib/python2.6/site-packages/werkzeug/local.py", line 347, in __getattr__
    return getattr(self._get_current_object(), name)
AttributeError: 'Request' object has no attribute 'get'
2019-03-01 11:14:25,564 level-ERROR    Exception on /ding [GET]
Traceback (most recent call last):
  File "/usr/lib/python2.6/site-packages/flask/app.py", line 1982, in wsgi_app
    response = self.full_dispatch_request()
  File "/usr/lib/python2.6/site-packages/flask/app.py", line 1614, in full_dispatch_request
    rv = self.handle_user_exception(e)
  File "/usr/lib/python2.6/site-packages/flask/app.py", line 1517, in handle_user_exception
    reraise(exc_type, exc_value, tb)
  File "/usr/lib/python2.6/site-packages/flask/app.py", line 1612, in full_dispatch_request
    rv = self.dispatch_request()
  File "/usr/lib/python2.6/site-packages/flask/app.py", line 1598, in dispatch_request
    return self.view_functions[rule.endpoint](**req.view_args)
  File "/data/BxcqMloms/app/main/views.py", line 59, in infoindex
    username = request.args.get["name"]
TypeError: 'instancemethod' object is unsubscriptable
2019-03-01 11:14:26,769 level-ERROR    Exception on /ding [GET]
Traceback (most recent call last):
  File "/usr/lib/python2.6/site-packages/flask/app.py", line 1982, in wsgi_app
    response = self.full_dispatch_request()
  File "/usr/lib/python2.6/site-packages/flask/app.py", line 1614, in full_dispatch_request
    rv = self.handle_user_exception(e)
  File "/usr/lib/python2.6/site-packages/flask/app.py", line 1517, in handle_user_exception
    reraise(exc_type, exc_value, tb)
  File "/usr/lib/python2.6/site-packages/flask/app.py", line 1612, in full_dispatch_request
    rv = self.dispatch_request()
  File "/usr/lib/python2.6/site-packages/flask/app.py", line 1598, in dispatch_request
    return self.view_functions[rule.endpoint](**req.view_args)
  File "/data/BxcqMloms/app/main/views.py", line 59, in infoindex
    username = request.args.get["name"]
TypeError: 'instancemethod' object is unsubscriptable
2019-03-01 11:14:27,265 level-ERROR    Exception on /ding [GET]
Traceback (most recent call last):
  File "/usr/lib/python2.6/site-packages/flask/app.py", line 1982, in wsgi_app
    response = self.full_dispatch_request()
  File "/usr/lib/python2.6/site-packages/flask/app.py", line 1614, in full_dispatch_request
    rv = self.handle_user_exception(e)
  File "/usr/lib/python2.6/site-packages/flask/app.py", line 1517, in handle_user_exception
    reraise(exc_type, exc_value, tb)
  File "/usr/lib/python2.6/site-packages/flask/app.py", line 1612, in full_dispatch_request
    rv = self.dispatch_request()
  File "/usr/lib/python2.6/site-packages/flask/app.py", line 1598, in dispatch_request
    return self.view_functions[rule.endpoint](**req.view_args)
  File "/data/BxcqMloms/app/main/views.py", line 59, in infoindex
    username = request.args.get["name"]
TypeError: 'instancemethod' object is unsubscriptable
2019-03-01 11:14:27,564 level-ERROR    Exception on /ding [GET]
Traceback (most recent call last):
  File "/usr/lib/python2.6/site-packages/flask/app.py", line 1982, in wsgi_app
    response = self.full_dispatch_request()
  File "/usr/lib/python2.6/site-packages/flask/app.py", line 1614, in full_dispatch_request
    rv = self.handle_user_exception(e)
  File "/usr/lib/python2.6/site-packages/flask/app.py", line 1517, in handle_user_exception
    reraise(exc_type, exc_value, tb)
  File "/usr/lib/python2.6/site-packages/flask/app.py", line 1612, in full_dispatch_request
    rv = self.dispatch_request()
  File "/usr/lib/python2.6/site-packages/flask/app.py", line 1598, in dispatch_request
    return self.view_functions[rule.endpoint](**req.view_args)
  File "/data/BxcqMloms/app/main/views.py", line 59, in infoindex
    username = request.args.get["name"]
TypeError: 'instancemethod' object is unsubscriptable
2019-03-01 11:14:27,856 level-ERROR    Exception on /ding [GET]
Traceback (most recent call last):
  File "/usr/lib/python2.6/site-packages/flask/app.py", line 1982, in wsgi_app
    response = self.full_dispatch_request()
  File "/usr/lib/python2.6/site-packages/flask/app.py", line 1614, in full_dispatch_request
    rv = self.handle_user_exception(e)
  File "/usr/lib/python2.6/site-packages/flask/app.py", line 1517, in handle_user_exception
    reraise(exc_type, exc_value, tb)
  File "/usr/lib/python2.6/site-packages/flask/app.py", line 1612, in full_dispatch_request
    rv = self.dispatch_request()
  File "/usr/lib/python2.6/site-packages/flask/app.py", line 1598, in dispatch_request
    return self.view_functions[rule.endpoint](**req.view_args)
  File "/data/BxcqMloms/app/main/views.py", line 59, in infoindex
    username = request.args.get["name"]
TypeError: 'instancemethod' object is unsubscriptable
2019-03-01 11:16:48,520 level-ERROR    Exception on /ding [GET]
Traceback (most recent call last):
  File "/usr/lib/python2.6/site-packages/flask/app.py", line 1982, in wsgi_app
    response = self.full_dispatch_request()
  File "/usr/lib/python2.6/site-packages/flask/app.py", line 1614, in full_dispatch_request
    rv = self.handle_user_exception(e)
  File "/usr/lib/python2.6/site-packages/flask/app.py", line 1517, in handle_user_exception
    reraise(exc_type, exc_value, tb)
  File "/usr/lib/python2.6/site-packages/flask/app.py", line 1612, in full_dispatch_request
    rv = self.dispatch_request()
  File "/usr/lib/python2.6/site-packages/flask/app.py", line 1598, in dispatch_request
    return self.view_functions[rule.endpoint](**req.view_args)
  File "/data/BxcqMloms/app/main/views.py", line 62, in infoindex
    strbyte = base64.b64decode(jessionid)
NameError: global name 'base64' is not defined
2019-03-01 11:16:49,633 level-ERROR    Exception on /ding [GET]
Traceback (most recent call last):
  File "/usr/lib/python2.6/site-packages/flask/app.py", line 1982, in wsgi_app
    response = self.full_dispatch_request()
  File "/usr/lib/python2.6/site-packages/flask/app.py", line 1614, in full_dispatch_request
    rv = self.handle_user_exception(e)
  File "/usr/lib/python2.6/site-packages/flask/app.py", line 1517, in handle_user_exception
    reraise(exc_type, exc_value, tb)
  File "/usr/lib/python2.6/site-packages/flask/app.py", line 1612, in full_dispatch_request
    rv = self.dispatch_request()
  File "/usr/lib/python2.6/site-packages/flask/app.py", line 1598, in dispatch_request
    return self.view_functions[rule.endpoint](**req.view_args)
  File "/data/BxcqMloms/app/main/views.py", line 62, in infoindex
    strbyte = base64.b64decode(jessionid)
NameError: global name 'base64' is not defined
2019-03-01 11:16:50,188 level-ERROR    Exception on /ding [GET]
Traceback (most recent call last):
  File "/usr/lib/python2.6/site-packages/flask/app.py", line 1982, in wsgi_app
    response = self.full_dispatch_request()
  File "/usr/lib/python2.6/site-packages/flask/app.py", line 1614, in full_dispatch_request
    rv = self.handle_user_exception(e)
  File "/usr/lib/python2.6/site-packages/flask/app.py", line 1517, in handle_user_exception
    reraise(exc_type, exc_value, tb)
  File "/usr/lib/python2.6/site-packages/flask/app.py", line 1612, in full_dispatch_request
    rv = self.dispatch_request()
  File "/usr/lib/python2.6/site-packages/flask/app.py", line 1598, in dispatch_request
    return self.view_functions[rule.endpoint](**req.view_args)
  File "/data/BxcqMloms/app/main/views.py", line 62, in infoindex
    strbyte = base64.b64decode(jessionid)
NameError: global name 'base64' is not defined
2019-03-01 11:23:19,633 level-ERROR    Exception on /phyServerManage [GET]
Traceback (most recent call last):
  File "/usr/lib/python2.6/site-packages/flask/app.py", line 1982, in wsgi_app
    response = self.full_dispatch_request()
  File "/usr/lib/python2.6/site-packages/flask/app.py", line 1614, in full_dispatch_request
    rv = self.handle_user_exception(e)
  File "/usr/lib/python2.6/site-packages/flask/app.py", line 1517, in handle_user_exception
    reraise(exc_type, exc_value, tb)
  File "/usr/lib/python2.6/site-packages/flask/app.py", line 1612, in full_dispatch_request
    rv = self.dispatch_request()
  File "/usr/lib/python2.6/site-packages/flask/app.py", line 1598, in dispatch_request
    return self.view_functions[rule.endpoint](**req.view_args)
  File "/data/BxcqMloms/app/decorators.py", line 7, in decorated_function
    if permission in session['permissons']:
  File "/usr/lib/python2.6/site-packages/werkzeug/local.py", line 377, in <lambda>
    __getitem__ = lambda x, i: x._get_current_object()[i]
KeyError: 'permissons'
2019-03-01 13:55:43,580 level-ERROR    Exception on /ding [GET]
Traceback (most recent call last):
  File "/usr/lib/python2.6/site-packages/flask/app.py", line 1982, in wsgi_app
    response = self.full_dispatch_request()
  File "/usr/lib/python2.6/site-packages/flask/app.py", line 1614, in full_dispatch_request
    rv = self.handle_user_exception(e)
  File "/usr/lib/python2.6/site-packages/flask/app.py", line 1517, in handle_user_exception
    reraise(exc_type, exc_value, tb)
  File "/usr/lib/python2.6/site-packages/flask/app.py", line 1612, in full_dispatch_request
    rv = self.dispatch_request()
  File "/usr/lib/python2.6/site-packages/flask/app.py", line 1598, in dispatch_request
    return self.view_functions[rule.endpoint](**req.view_args)
  File "/data/BxcqMloms/app/main/views.py", line 67, in infoindex
    session['permissons'] = permissionlist
NameError: global name 'permissionlist' is not defined
2019-03-01 14:11:38,766 level-ERROR    Exception on /phyServerManage [GET]
Traceback (most recent call last):
  File "/usr/lib/python2.6/site-packages/flask/app.py", line 1982, in wsgi_app
    response = self.full_dispatch_request()
  File "/usr/lib/python2.6/site-packages/flask/app.py", line 1614, in full_dispatch_request
    rv = self.handle_user_exception(e)
  File "/usr/lib/python2.6/site-packages/flask/app.py", line 1517, in handle_user_exception
    reraise(exc_type, exc_value, tb)
  File "/usr/lib/python2.6/site-packages/flask/app.py", line 1612, in full_dispatch_request
    rv = self.dispatch_request()
  File "/usr/lib/python2.6/site-packages/flask/app.py", line 1598, in dispatch_request
    return self.view_functions[rule.endpoint](**req.view_args)
  File "/data/BxcqMloms/app/decorators.py", line 20, in decorated_view
    if request.method in EXEMPT_METHODS:
NameError: global name 'EXEMPT_METHODS' is not defined
2019-03-01 14:19:02,721 level-ERROR    Exception on /phyServerManage [GET]
Traceback (most recent call last):
  File "/usr/lib/python2.6/site-packages/flask/app.py", line 1982, in wsgi_app
    response = self.full_dispatch_request()
  File "/usr/lib/python2.6/site-packages/flask/app.py", line 1614, in full_dispatch_request
    rv = self.handle_user_exception(e)
  File "/usr/lib/python2.6/site-packages/flask/app.py", line 1517, in handle_user_exception
    reraise(exc_type, exc_value, tb)
  File "/usr/lib/python2.6/site-packages/flask/app.py", line 1612, in full_dispatch_request
    rv = self.dispatch_request()
  File "/usr/lib/python2.6/site-packages/flask/app.py", line 1598, in dispatch_request
    return self.view_functions[rule.endpoint](**req.view_args)
  File "/data/BxcqMloms/app/decorators.py", line 19, in decorated_view
    if request.method in EXEMPT_METHODS:
NameError: global name 'EXEMPT_METHODS' is not defined
2019-03-01 14:39:06,705 level-ERROR    Exception on /phyServerManage [GET]
Traceback (most recent call last):
  File "/usr/lib/python2.6/site-packages/flask/app.py", line 1982, in wsgi_app
    response = self.full_dispatch_request()
  File "/usr/lib/python2.6/site-packages/flask/app.py", line 1615, in full_dispatch_request
    return self.finalize_request(rv)
  File "/usr/lib/python2.6/site-packages/flask/app.py", line 1630, in finalize_request
    response = self.make_response(rv)
  File "/usr/lib/python2.6/site-packages/flask/app.py", line 1725, in make_response
    raise ValueError('View function did not return a response')
ValueError: View function did not return a response
2019-03-01 14:51:46,615 level-ERROR    Exception on /phyServerManage [GET]
Traceback (most recent call last):
  File "/usr/lib/python2.6/site-packages/flask/app.py", line 1982, in wsgi_app
    response = self.full_dispatch_request()
  File "/usr/lib/python2.6/site-packages/flask/app.py", line 1614, in full_dispatch_request
    rv = self.handle_user_exception(e)
  File "/usr/lib/python2.6/site-packages/flask/app.py", line 1517, in handle_user_exception
    reraise(exc_type, exc_value, tb)
  File "/usr/lib/python2.6/site-packages/flask/app.py", line 1612, in full_dispatch_request
    rv = self.dispatch_request()
  File "/usr/lib/python2.6/site-packages/flask/app.py", line 1598, in dispatch_request
    return self.view_functions[rule.endpoint](**req.view_args)
  File "/data/BxcqMloms/app/decorators.py", line 19, in decorated_view
    return func(*aogs,**kwargs)
NameError: global name 'aogs' is not defined
